<?xml version="1.0" ?>
<!-- =================================================================================== -->
<!-- |    This document was autogenerated by xacro from summit_xls_std_V2.urdf.xacro   | -->
<!-- |    EDITING THIS FILE BY HAND IS NOT RECOMMENDED                                 | -->
<!-- =================================================================================== -->
<robot name="summit_xl" xmlns:controller="http://playerstage.sourceforge.net/gazebo/xmlschema/#controller" xmlns:xacro="http://www.ros.org/wiki/xacro">
  <!-- ***************** -->
  <!-- Imported elements -->
  <!-- ***************** -->
  <!-- First we import all posible elements defined in the urdf.xacro files. All these elements are defined as macro:xacros -->
  <!--xacro:macro name="ros_wam_control_plugin" >
  <gazebo>
  	<plugin name="wam_joint_control_plugin" filename="libset_speed_joint_plugin.so">
		<activate_pid_control>no</activate_pid_control>                
	</plugin>
	</gazebo>	
  </xacro:macro-->
  <gazebo>
    <plugin filename="libgazebo_ros_p3d.so" name="p3d_base_controller">
      <alwaysOn>true</alwaysOn>
      <updateRate>50.0</updateRate>
      <bodyName>summit_xl_a_base_footprint</bodyName>
      <topicName>ground_truth/state</topicName>
      <gaussianNoise>0.01</gaussianNoise>
      <frameName>world</frameName>
      <xyzOffset>0 0 0</xyzOffset>
      <rpyOffset>0 0 0</rpyOffset>
    </plugin>
  </gazebo>
  <gazebo reference="base_footprint">
    <material>Gazebo/Green</material>
  </gazebo>
  <!-- in kg-->
  <!-- in kg-->
  <!-- Hollow forearm macros -->
  <!--<xacro:macro name="wam_hollow_forearm" params="prefix">-->
  <!--<joint name="${prefix}/elbow_joint" type="revolute">-->
  <!--<parent link="${prefix}/upper_arm_link"/>-->
  <!--<child link="${prefix}/forearm_link"/>-->
  <!--<origin xyz="0.045 -0.55 0" rpy="${0.5 * PI} 0 0"/>-->
  <!--<axis xyz="0 1 0"/>-->
  <!--<limit effort="15" lower="-0.9" upper="${PI}" velocity="0.50"/>-->
  <!--[> <safety_controller k_position="100" k_velocity="3" soft_lower_limit="-100.0" soft_upper_limit="100.0" /> <]-->
  <!--<dynamics damping="0.1" friction="100.0"/>-->
  <!--</joint>-->
  <!--<link name="${prefix}/forearm_link" >-->
  <!--<inertial>-->
  <!--<origin xyz="0 0 0" />-->
  <!--<mass value="3.20016804" />-->
  <!--<origin xyz="-0.04001488 -.00022942 .13271662" rpy="0 0 0" />-->
  <!--<inertia  ixx="0.01491672" ixy="0.00001741"   ixz="-0.00150604"-->
  <!--iyy="0.01482988"   iyz="-0.00002109"-->
  <!--izz="0.00294463" />-->
  <!--</inertial>-->
  <!--<visual>-->
  <!--<material name="WAMGrey">-->
  <!--<color rgba="0.7 0.7 0.7 1.0"/>-->
  <!--</material>-->
  <!--<origin xyz="0 0 0" rpy="-${PI} 0 0" />-->
  <!--<geometry>-->
  <!--<mesh filename="${models_path}/meshes/wamForeArmLink4.DAE"/>-->
  <!--</geometry>-->
  <!--</visual>-->
  <!--<collision>-->
  <!--<origin xyz="0 0 0" rpy="-${PI} 0 0" />-->
  <!--<geometry>-->
  <!--<mesh filename="${models_path}/meshes/wamForeArmLink4.stl"/>-->
  <!--</geometry>-->
  <!--</collision>-->
  <!--</link>-->
  <!--</xacro:macro>-->
  <!--<xacro:macro name="wam_hollow_wrist" params="prefix">-->
  <!--<joint name="${prefix}/UpperWristJoint" type="fixed">-->
  <!--<parent link="${prefix}/ForeArmLink"/>-->
  <!--<child link="${prefix}/LowerWristPalmLink"/>-->
  <!--<origin xyz="-0.045 0 .35" rpy="-${0.5 * PI} 0 ${0.5 * PI}"/>-->
  <!--<axis xyz="0 -1 0"/>-->
  <!--<limit effort="5" lower="-4.8" upper="1.3" velocity="0.20"/>-->
  <!--[> <safety_controller k_position="100" k_velocity="3" soft_lower_limit="-100.0" soft_upper_limit="100.0" /> <]-->
  <!--<dynamics damping="0.1" friction="100.0"/>-->
  <!--</joint>-->
  <!--<link name="${prefix}/LowerWristPalmLink" >-->
  <!--<inertial>-->
  <!--<origin xyz="0.00008921 0.00511217 0.00435824" />-->
  <!--<mass value="1.12376019" />-->
  <!--<inertia  ixx="0.00005029" ixy="0.00000020"  ixz="0.00007582"-->
  <!--iyy="0.00007582"  iyz="-0.00000359"-->
  <!--izz="0.00006270" />-->
  <!--</inertial>-->
  <!--<visual>-->
  <!--<material name="WAMGrey">-->
  <!--<color rgba="0.7 0.7 0.7 1.0"/>-->
  <!--</material>-->
  <!--<origin xyz="0 0.02711 0" rpy="${PI} 0 0" />-->
  <!--<geometry>-->
  <!--<mesh filename="${models_path}/meshes/wamUpperWristYawLink.DAE"/>-->
  <!--</geometry>-->
  <!--</visual>-->
  <!--<collision>-->
  <!--<origin xyz="0 0.02711 0" rpy="${PI} 0 0" />-->
  <!--<geometry>-->
  <!--<mesh filename="${models_path}/meshes/wamUpperWristYawLink5.stl"/>-->
  <!--</geometry>-->
  <!--</collision>-->
  <!--</link>-->
  <!--</xacro:macro>-->
  <!-- Palm with ForceTorque macros -->
  <!--<xacro:macro name="LowerWristFT" params="prefix">-->
  <!--<joint name="${prefix}/LowerWristYawJoint" type="revolute">-->
  <!--<parent link="${prefix}/UpperWristPitchLink"/>-->
  <!--<child link="${prefix}/LowerWristYawLink"/>-->
  <!--<origin xyz="0 0 0.06713340" rpy="0 0 0"/>-->
  <!--<axis xyz="0 0 1"/>-->
  <!--<limit effort="5" lower="-2.95" upper="2.95" velocity="0.20"/>[> 2.95 is a limit taken in from 3 due to saftey and differences between arms. <]-->
  <!--[> <safety_controller k_position="100" k_velocity="3" soft_lower_limit="-100.0" soft_upper_limit="100.0" /> <]-->
  <!--<dynamics damping="0.1" friction="100.0"/>-->
  <!--</joint>-->
  <!--<link name="${prefix}/LowerWristYawLink" >-->
  <!--<inertial>-->
  <!--<origin xyz="-0.00000134 -0.00228167 -0.00000141" rpy="0 0 0" />-->
  <!--<mass value="0.17286134" />-->
  <!--<inertia  ixx="0.00010859" ixy="0.00000000"  ixz="-0.00000000"-->
  <!--iyy="0.00020683"  iyz="-0.0000000"-->
  <!--izz="0.00010851" />-->
  <!--</inertial>-->
  <!--<visual>-->
  <!--<material name="WAMGrey">-->
  <!--<color rgba="0.7 0.7 0.7 1.0"/>-->
  <!--</material>-->
  <!--<origin xyz="0 0 0" rpy="0 0 0" />-->
  <!--<geometry>-->
  <!--<mesh filename="${models_path}/meshes/forceTorqueSensor.DAE"/>-->
  <!--</geometry>-->
  <!--</visual>-->
  <!--<collision>-->
  <!--<origin xyz="0 0 0" rpy="0 0 0" />-->
  <!--<geometry>-->
  <!--<mesh filename="${models_path}/meshes/forceTorqueSensor.stl"/>-->
  <!--</geometry>-->
  <!--</collision>-->
  <!--</link>-->
  <!--</xacro:macro>-->
  <!-- Hollow forearm macros -->
  <!--<xacro:macro name="wam_hollow_forearm" params="prefix">-->
  <!--<joint name="${prefix}/elbow_joint" type="revolute">-->
  <!--<parent link="${prefix}/upper_arm_link"/>-->
  <!--<child link="${prefix}/forearm_link"/>-->
  <!--<origin xyz="0.045 -0.55 0" rpy="${0.5 * PI} 0 0"/>-->
  <!--<axis xyz="0 1 0"/>-->
  <!--<limit effort="15" lower="-0.9" upper="${PI}" velocity="0.50"/>-->
  <!--[> <safety_controller k_position="100" k_velocity="3" soft_lower_limit="-100.0" soft_upper_limit="100.0" /> <]-->
  <!--<dynamics damping="0.1" friction="100.0"/>-->
  <!--</joint>-->
  <!--<link name="${prefix}/forearm_link" >-->
  <!--<inertial>-->
  <!--<origin xyz="0 0 0" />-->
  <!--<mass value="3.20016804" />-->
  <!--<origin xyz="-0.04001488 -.00022942 .13271662" rpy="0 0 0" />-->
  <!--<inertia  ixx="0.01491672" ixy="0.00001741"   ixz="-0.00150604"-->
  <!--iyy="0.01482988"   iyz="-0.00002109"-->
  <!--izz="0.00294463" />-->
  <!--</inertial>-->
  <!--<visual>-->
  <!--<material name="WAMGrey">-->
  <!--<color rgba="0.7 0.7 0.7 1.0"/>-->
  <!--</material>-->
  <!--<origin xyz="0 0 0" rpy="-${PI} 0 0" />-->
  <!--<geometry>-->
  <!--<mesh filename="${models_path}/meshes/wamForeArmLink4.DAE"/>-->
  <!--</geometry>-->
  <!--</visual>-->
  <!--<collision>-->
  <!--<origin xyz="0 0 0" rpy="-${PI} 0 0" />-->
  <!--<geometry>-->
  <!--<mesh filename="${models_path}/meshes/wamForeArmLink4.stl"/>-->
  <!--</geometry>-->
  <!--</collision>-->
  <!--</link>-->
  <!--</xacro:macro>-->
  <!--<xacro:macro name="wam_hollow_wrist" params="prefix">-->
  <!--<joint name="${prefix}/UpperWristJoint" type="fixed">-->
  <!--<parent link="${prefix}/ForeArmLink"/>-->
  <!--<child link="${prefix}/LowerWristPalmLink"/>-->
  <!--<origin xyz="-0.045 0 .35" rpy="-${0.5 * PI} 0 ${0.5 * PI}"/>-->
  <!--<axis xyz="0 -1 0"/>-->
  <!--<limit effort="5" lower="-4.8" upper="1.3" velocity="0.20"/>-->
  <!--[> <safety_controller k_position="100" k_velocity="3" soft_lower_limit="-100.0" soft_upper_limit="100.0" /> <]-->
  <!--<dynamics damping="0.1" friction="100.0"/>-->
  <!--</joint>-->
  <!--<link name="${prefix}/LowerWristPalmLink" >-->
  <!--<inertial>-->
  <!--<origin xyz="0.00008921 0.00511217 0.00435824" />-->
  <!--<mass value="1.12376019" />-->
  <!--<inertia  ixx="0.00005029" ixy="0.00000020"  ixz="0.00007582"-->
  <!--iyy="0.00007582"  iyz="-0.00000359"-->
  <!--izz="0.00006270" />-->
  <!--</inertial>-->
  <!--<visual>-->
  <!--<material name="WAMGrey">-->
  <!--<color rgba="0.7 0.7 0.7 1.0"/>-->
  <!--</material>-->
  <!--<origin xyz="0 0.02711 0" rpy="${PI} 0 0" />-->
  <!--<geometry>-->
  <!--<mesh filename="${models_path}/meshes/wamUpperWristYawLink.DAE"/>-->
  <!--</geometry>-->
  <!--</visual>-->
  <!--<collision>-->
  <!--<origin xyz="0 0.02711 0" rpy="${PI} 0 0" />-->
  <!--<geometry>-->
  <!--<mesh filename="${models_path}/meshes/wamUpperWristYawLink5.stl"/>-->
  <!--</geometry>-->
  <!--</collision>-->
  <!--</link>-->
  <!--</xacro:macro>-->
  <!-- Palm with ForceTorque macros -->
  <!--<xacro:macro name="LowerWristFT" params="prefix">-->
  <!--<joint name="${prefix}/LowerWristYawJoint" type="revolute">-->
  <!--<parent link="${prefix}/UpperWristPitchLink"/>-->
  <!--<child link="${prefix}/LowerWristYawLink"/>-->
  <!--<origin xyz="0 0 0.06713340" rpy="0 0 0"/>-->
  <!--<axis xyz="0 0 1"/>-->
  <!--<limit effort="5" lower="-2.95" upper="2.95" velocity="0.20"/>[> 2.95 is a limit taken in from 3 due to saftey and differences between arms. <]-->
  <!--[> <safety_controller k_position="100" k_velocity="3" soft_lower_limit="-100.0" soft_upper_limit="100.0" /> <]-->
  <!--<dynamics damping="0.1" friction="100.0"/>-->
  <!--</joint>-->
  <!--<link name="${prefix}/LowerWristYawLink" >-->
  <!--<inertial>-->
  <!--<origin xyz="-0.00000134 -0.00228167 -0.00000141" rpy="0 0 0" />-->
  <!--<mass value="0.17286134" />-->
  <!--<inertia  ixx="0.00010859" ixy="0.00000000"  ixz="-0.00000000"-->
  <!--iyy="0.00020683"  iyz="-0.0000000"-->
  <!--izz="0.00010851" />-->
  <!--</inertial>-->
  <!--<visual>-->
  <!--<material name="WAMGrey">-->
  <!--<color rgba="0.7 0.7 0.7 1.0"/>-->
  <!--</material>-->
  <!--<origin xyz="0 0 0" rpy="0 0 0" />-->
  <!--<geometry>-->
  <!--<mesh filename="${models_path}/meshes/forceTorqueSensor.DAE"/>-->
  <!--</geometry>-->
  <!--</visual>-->
  <!--<collision>-->
  <!--<origin xyz="0 0 0" rpy="0 0 0" />-->
  <!--<geometry>-->
  <!--<mesh filename="${models_path}/meshes/forceTorqueSensor.stl"/>-->
  <!--</geometry>-->
  <!--</collision>-->
  <!--</link>-->
  <!--</xacro:macro>-->
  <!-- Materials -->
  <material name="WAMGrey">
    <color rgba="0.7 0.7 0.7 1.0"/>
  </material>
  <!-- This file unifies all sensors that can be used on simulation, defined as xacro:macros -->
  <material name="aluminum">
    <color rgba="0.5 0.5 0.5 1"/>
  </material>
  <gazebo>
    <plugin filename="libgazebo_ros_control.so" name="ros_control">
      <!--<robotNamespace>/summit_xl</robotNamespace>-->
      <robotParam>robot_description</robotParam>
      <controlPeriod>0.001</controlPeriod>
      <robotSimType>gazebo_ros_control/DefaultRobotHWSim</robotSimType>
      <legacyModeNS>true</legacyModeNS>
    </plugin>
  </gazebo>
  <!--xacro:ros_wam_control_plugin/-->
  <!-- *************** -->
  <!-- Robots Elements -->
  <!-- *************** -->
  <!-- Here we create the robot ele	ments using the xacro:macros imported at the beggining of this file -->
  <link name="summit_xl__base_footprint">
    <visual>
      <origin rpy="0 0 0" xyz="0 0 0"/>
      <geometry>
        <box size="0.001 0.001 0.001"/>
      </geometry>
    </visual>
  </link>
  <joint name="summit_xl__base_footprint_joint" type="fixed">
    <origin rpy="0 0 -1.57079632679" xyz="0 0 0.0"/>
    <!-- ${wheel_radius} property must be defined inside wheel description -->
    <parent link="summit_xl__base_footprint"/>
    <child link="summit_xl__base_link"/>
  </joint>
  <!-- BASE_LINK -->
  <link name="summit_xl__base_link">
    <inertial>
      <mass value="125.0"/>
      <origin xyz="0 0 0.37"/>
      <inertia ixx="6.853" ixy="0.0" ixz="0.0" iyy="1.391" iyz="0.0" izz="6.125"/>
    </inertial>
    <visual>
      <!-- <origin xyz="0 0 0" rpy="0 0 0" /> -->
      <origin rpy="0 0 0" xyz="0 0 0"/>
      <geometry>
        <!-- <mesh filename="package://summit_xl_description/meshes/bases/hls/summit_xl_hls.stl"/> -->
        <mesh filename="package://summit_xl_description/meshes/bases/Jack/base_link_summit.stl"/>
      </geometry>
      <material name="darkgrey">
        <color rgba="0.1 0.1 0.1 1"/>
      </material>
    </visual>
    <collision>
      <origin rpy="0 0 0 " xyz="0 0 0"/>
      <geometry>
        <!-- <mesh filename="package://summit_xl_description/meshes/bases/hls/summit_xl_hls.dae"/> -->
        <mesh filename="package://summit_xl_description/meshes/bases/Jack/base_link_summit.stl"/>
      </geometry>
    </collision>
  </link>
  <!-- DOCKING CONTACT -->
  <link name="summit_xl__base_docking_contact">
    </link>
  <joint name="summit_xl__base_docking_joint" type="fixed">
    <origin rpy="0 0 0" xyz="0.30 0 0.09"/>
    <parent link="summit_xl__base_link"/>
    <child link="summit_xl__base_docking_contact"/>
  </joint>
  <joint name="summit_xl__front_right_wheel_joint" type="continuous">
    <parent link="summit_xl__base_link"/>
    <child link="summit_xl__front_right_wheel_link"/>
    <origin rpy="0 0 1.57079632679" xyz="0.264 0.222 0.128"/>
    <axis rpy="0 0 0" xyz="0 1 0"/>
    <limit effort="100" velocity="100"/>
    <joint_properties damping="0.0" friction="0.0"/>
  </joint>
  <link name="summit_xl__front_right_wheel_link">
    <visual>
      <origin rpy="0 0 0" xyz="0 0 0"/>
      <geometry>
        <mesh filename="package://summit_xl_description/meshes/wheels/omni_wheel_2.dae"/>
      </geometry>
      <material name="darkgrey">
        <color rgba="0.2 0.2 0.2 1"/>
      </material>
    </visual>
    <collision>
      <origin rpy="1.57079632679 0 0" xyz="0 0 0"/>
      <geometry>
        <!--
          <sphere radius="${wheel_radius}" />
-->
        <!--
          <xacro:if value="${reflect}">
              <mesh filename="package://summit_xl_description/meshes/wheels/omni_wheel_1.dae" />
          </xacro:if>
          <xacro:unless value="${reflect}">
              <mesh filename="package://summit_xl_description/meshes/wheels/omni_wheel_2.dae" />
					</xacro:unless>
-->
        <cylinder length="0.14" radius="0.125"/>
      </geometry>
    </collision>
    <inertial>
      <mass value="6.5"/>
      <origin xyz="0 0 0"/>
      <inertia ixx="0.0360072916667" ixy="0" ixz="0" iyy="0.05078125" iyz="0" izz="0.0360072916667"/>
    </inertial>
  </link>
  <!-- Transmission is important to link the joints and the controller (see summit_xl_control/config/summit_xl_control.yaml)-->
  <transmission name="summit_xl__front_right_wheel_joint_trans">
    <type>transmission_interface/SimpleTransmission</type>
    <joint name="summit_xl__front_right_wheel_joint">
      <hardwareInterface>hardware_interface/VelocityJointInterface</hardwareInterface>
    </joint>
    <actuator name="summit_xl__front_right_wheel_joint_motor">
      <mechanicalReduction>1</mechanicalReduction>
    </actuator>
  </transmission>
  <gazebo reference="summit_xl__front_right_wheel_link">
    <mu1 value="1.0"/>
    <mu2 value="1.0"/>
    <kp value="10000000.0"/>
    <kd value="1.0"/>
    <fdir1 value="1 0 0"/>
    <turnGravityOff>false</turnGravityOff>
  </gazebo>
  <joint name="summit_xl__front_left_wheel_joint" type="continuous">
    <parent link="summit_xl__base_link"/>
    <child link="summit_xl__front_left_wheel_link"/>
    <origin rpy="0 0 1.57079632679" xyz="-0.264 0.222 0.128"/>
    <axis rpy="0 0 0" xyz="0 1 0"/>
    <limit effort="100" velocity="100"/>
    <joint_properties damping="0.0" friction="0.0"/>
  </joint>
  <link name="summit_xl__front_left_wheel_link">
    <visual>
      <origin rpy="0 0 0" xyz="0 0 0"/>
      <geometry>
        <mesh filename="package://summit_xl_description/meshes/wheels/omni_wheel_1.dae"/>
      </geometry>
      <material name="darkgrey">
        <color rgba="0.2 0.2 0.2 1"/>
      </material>
    </visual>
    <collision>
      <origin rpy="1.57079632679 0 0" xyz="0 0 0"/>
      <geometry>
        <!--
          <sphere radius="${wheel_radius}" />
-->
        <!--
          <xacro:if value="${reflect}">
              <mesh filename="package://summit_xl_description/meshes/wheels/omni_wheel_1.dae" />
          </xacro:if>
          <xacro:unless value="${reflect}">
              <mesh filename="package://summit_xl_description/meshes/wheels/omni_wheel_2.dae" />
					</xacro:unless>
-->
        <cylinder length="0.14" radius="0.125"/>
      </geometry>
    </collision>
    <inertial>
      <mass value="6.5"/>
      <origin xyz="0 0 0"/>
      <inertia ixx="0.0360072916667" ixy="0" ixz="0" iyy="0.05078125" iyz="0" izz="0.0360072916667"/>
    </inertial>
  </link>
  <!-- Transmission is important to link the joints and the controller (see summit_xl_control/config/summit_xl_control.yaml)-->
  <transmission name="summit_xl__front_left_wheel_joint_trans">
    <type>transmission_interface/SimpleTransmission</type>
    <joint name="summit_xl__front_left_wheel_joint">
      <hardwareInterface>hardware_interface/VelocityJointInterface</hardwareInterface>
    </joint>
    <actuator name="summit_xl__front_left_wheel_joint_motor">
      <mechanicalReduction>1</mechanicalReduction>
    </actuator>
  </transmission>
  <gazebo reference="summit_xl__front_left_wheel_link">
    <mu1 value="1.0"/>
    <mu2 value="1.0"/>
    <kp value="10000000.0"/>
    <kd value="1.0"/>
    <fdir1 value="1 0 0"/>
    <turnGravityOff>false</turnGravityOff>
  </gazebo>
  <joint name="summit_xl__back_left_wheel_joint" type="continuous">
    <parent link="summit_xl__base_link"/>
    <child link="summit_xl__back_left_wheel_link"/>
    <origin rpy="0 0 1.57079632679" xyz="-0.264 -0.223 0.128"/>
    <axis rpy="0 0 0" xyz="0 1 0"/>
    <limit effort="100" velocity="100"/>
    <joint_properties damping="0.0" friction="0.0"/>
  </joint>
  <link name="summit_xl__back_left_wheel_link">
    <visual>
      <origin rpy="0 0 0" xyz="0 0 0"/>
      <geometry>
        <mesh filename="package://summit_xl_description/meshes/wheels/omni_wheel_1.dae"/>
      </geometry>
      <material name="darkgrey">
        <color rgba="0.2 0.2 0.2 1"/>
      </material>
    </visual>
    <collision>
      <origin rpy="1.57079632679 0 0" xyz="0 0 0"/>
      <geometry>
        <!--
          <sphere radius="${wheel_radius}" />
-->
        <!--
          <xacro:if value="${reflect}">
              <mesh filename="package://summit_xl_description/meshes/wheels/omni_wheel_1.dae" />
          </xacro:if>
          <xacro:unless value="${reflect}">
              <mesh filename="package://summit_xl_description/meshes/wheels/omni_wheel_2.dae" />
					</xacro:unless>
-->
        <cylinder length="0.14" radius="0.125"/>
      </geometry>
    </collision>
    <inertial>
      <mass value="6.5"/>
      <origin xyz="0 0 0"/>
      <inertia ixx="0.0360072916667" ixy="0" ixz="0" iyy="0.05078125" iyz="0" izz="0.0360072916667"/>
    </inertial>
  </link>
  <!-- Transmission is important to link the joints and the controller (see summit_xl_control/config/summit_xl_control.yaml)-->
  <transmission name="summit_xl__back_left_wheel_joint_trans">
    <type>transmission_interface/SimpleTransmission</type>
    <joint name="summit_xl__back_left_wheel_joint">
      <hardwareInterface>hardware_interface/VelocityJointInterface</hardwareInterface>
    </joint>
    <actuator name="summit_xl__back_left_wheel_joint_motor">
      <mechanicalReduction>1</mechanicalReduction>
    </actuator>
  </transmission>
  <gazebo reference="summit_xl__back_left_wheel_link">
    <mu1 value="1.0"/>
    <mu2 value="1.0"/>
    <kp value="10000000.0"/>
    <kd value="1.0"/>
    <fdir1 value="1 0 0"/>
    <turnGravityOff>false</turnGravityOff>
  </gazebo>
  <joint name="summit_xl__back_right_wheel_joint" type="continuous">
    <parent link="summit_xl__base_link"/>
    <child link="summit_xl__back_right_wheel_link"/>
    <origin rpy="0 0 1.57079632679" xyz="0.264 -0.223 0.128"/>
    <axis rpy="0 0 0" xyz="0 1 0"/>
    <limit effort="100" velocity="100"/>
    <joint_properties damping="0.0" friction="0.0"/>
  </joint>
  <link name="summit_xl__back_right_wheel_link">
    <visual>
      <origin rpy="0 0 0" xyz="0 0 0"/>
      <geometry>
        <mesh filename="package://summit_xl_description/meshes/wheels/omni_wheel_2.dae"/>
      </geometry>
      <material name="darkgrey">
        <color rgba="0.2 0.2 0.2 1"/>
      </material>
    </visual>
    <collision>
      <origin rpy="1.57079632679 0 0" xyz="0 0 0"/>
      <geometry>
        <!--
          <sphere radius="${wheel_radius}" />
-->
        <!--
          <xacro:if value="${reflect}">
              <mesh filename="package://summit_xl_description/meshes/wheels/omni_wheel_1.dae" />
          </xacro:if>
          <xacro:unless value="${reflect}">
              <mesh filename="package://summit_xl_description/meshes/wheels/omni_wheel_2.dae" />
					</xacro:unless>
-->
        <cylinder length="0.14" radius="0.125"/>
      </geometry>
    </collision>
    <inertial>
      <mass value="6.5"/>
      <origin xyz="0 0 0"/>
      <inertia ixx="0.0360072916667" ixy="0" ixz="0" iyy="0.05078125" iyz="0" izz="0.0360072916667"/>
    </inertial>
  </link>
  <!-- Transmission is important to link the joints and the controller (see summit_xl_control/config/summit_xl_control.yaml)-->
  <transmission name="summit_xl__back_right_wheel_joint_trans">
    <type>transmission_interface/SimpleTransmission</type>
    <joint name="summit_xl__back_right_wheel_joint">
      <hardwareInterface>hardware_interface/VelocityJointInterface</hardwareInterface>
    </joint>
    <actuator name="summit_xl__back_right_wheel_joint_motor">
      <mechanicalReduction>1</mechanicalReduction>
    </actuator>
  </transmission>
  <gazebo reference="summit_xl__back_right_wheel_link">
    <mu1 value="1.0"/>
    <mu2 value="1.0"/>
    <kp value="10000000.0"/>
    <kd value="1.0"/>
    <fdir1 value="1 0 0"/>
    <turnGravityOff>false</turnGravityOff>
  </gazebo>
  <joint name="summit_xl__imu_joint" type="fixed">
    <axis xyz="1 0 0"/>
    <!--origin xyz="0 0 0.2825"/-->
    <origin rpy="0 0 0" xyz="-0.18 0.0 0.170"/>
    <parent link="summit_xl__base_link"/>
    <child link="summit_xl__imu_link"/>
  </joint>
  <link name="summit_xl__imu_link">
    <inertial>
      <mass value="0.001"/>
      <origin rpy="0 0 0" xyz="0 0 0"/>
      <inertia ixx="0.0001" ixy="0" ixz="0" iyy="0.000001" iyz="0" izz="0.0001"/>
    </inertial>
    <visual>
      <origin rpy="0 0 0" xyz="0 0 0"/>
      <geometry>
        <box size="0.001 0.001 0.001"/>
      </geometry>
    </visual>
    <collision>
      <origin rpy="0 0 0" xyz="0 0 0"/>
      <geometry>
        <box size=".001 .001 .001"/>
      </geometry>
    </collision>
  </link>
  <gazebo>
    <plugin filename="libhector_gazebo_ros_imu.so" name="summit_xl__imu_controller">
      <alwaysOn>true</alwaysOn>
      <topicName>imu/data</topicName>
      <serviceName>summit_xl__imuimu/service</serviceName>
      <bodyName>summit_xl__imu_link</bodyName>
      <frameId>summit_xl__imu_link</frameId>
      <updateRate>50.0</updateRate>
      <gaussianNoise>0.005</gaussianNoise>
      <!-- orientation parameters -->
      <yawOffset>0.0</yawOffset>
      <!--<yawOffset>0.0</yawOffset>-->
      <yawDrift>0.02</yawDrift>
      <!--<yawDrift>0.0</yawDrift>-->
      <yawGaussianNoise>0.01</yawGaussianNoise>
      <!--<yawGaussianNoise>0.0004</yawGaussianNoise>-->
      <!-- angular velocities parameters -->
      <rateOffset>0.0 0.0 0.0</rateOffset>
      <rateDrift>0.002 0.002 0.002</rateDrift>
      <!--<rateDrift>0.0 0.0 0.0</rateDrift>-->
      <rateGaussianNoise>0.001 0.001 0.001</rateGaussianNoise>
      <!--<rateGaussianNoise>0.004 0.004 0.004</rateGaussianNoise>-->
      <!-- linear accelerations parameters -->
      <accelOffset>0.0 0.0 0.0</accelOffset>
      <accelDrift>0.005 0.005 0.005</accelDrift>
      <!--<accelDrift>0.0 0.0 0.0</accelDrift>-->
      <accelGaussianNoise>0.005 0.005 0.005</accelGaussianNoise>
      <!--<accelGaussianNoise>0.004 0.004 0.004</accelGaussianNoise>-->
    </plugin>
  </gazebo>
  <!-- Structures -->
  <!--xacro:structure_laser prefix="$(arg prefix)front_laser_structure" parent="$(arg prefix)base_link">
			<origin xyz="0.303 -0.160 0.155" rpy="0 0 0" />
		</xacro:structure_laser>
		<xacro:structure_laser prefix="$(arg prefix)rear_laser_structure" parent="$(arg prefix)base_link">
			<origin xyz="-0.303 0.160 0.155" rpy="0 0 ${PI}" />
		</xacro:structure_laser-->
  <link name="summit_xl__front_laser_link">
	</link>
  <joint name="summit_xl__front_laser_joint" type="fixed">
    <parent link="summit_xl__base_link"/>
    <child link="summit_xl__front_laser_link"/>
    <origin rpy="0 0 -0.785398163397" xyz="0.24457 0.362 0.2824"/>
  </joint>
  <joint name="summit_xl__front_laser_base_joint" type="fixed">
    <origin rpy="0 0 0" xyz="0.00 0 -0.05"/>
    <parent link="summit_xl__front_laser_link"/>
    <child link="summit_xl__front_laser_base_link"/>
  </joint>
  <link name="summit_xl__front_laser_base_link">
    <collision>
      <origin rpy="0 0 0" xyz="0 0 0.0"/>
      <geometry>
        <box size="0.010 0.010 0.010"/>
      </geometry>
    </collision>
    <visual>
      <origin rpy="0 0 0" xyz="0 0 0.0"/>
      <geometry>
        <mesh filename="package://robotnik_sensors/meshes/hokuyo_ust_10lx.dae"/>
      </geometry>
    </visual>
    <inertial>
      <mass value="1e-5"/>
      <origin rpy="0 0 0" xyz="0 0 0"/>
      <inertia ixx="1e-6" ixy="0" ixz="0" iyy="1e-6" iyz="0" izz="1e-6"/>
    </inertial>
  </link>
  <gazebo reference="summit_xl__front_laser_link">
    <sensor name="summit_xl__front_laser_sensor" type="ray">
      <pose>0 0 0 0 0 0</pose>
      <visualize>false</visualize>
      <update_rate>40</update_rate>
      <ray>
        <scan>
          <horizontal>
            <samples>1081</samples>
            <resolution>1</resolution>
            <min_angle>-2.3562</min_angle>
            <max_angle>2.3562</max_angle>
          </horizontal>
        </scan>
        <range>
          <min>0.06</min>
          <max>10.0</max>
          <!-- resolution>0.004363323</resolution -->
          <resolution>0.004359297</resolution>
          <!-- resolution>0.001</resolution -->
        </range>
        <noise>
          <type>gaussian</type>
          <mean>0.0</mean>
          <stddev>0.01</stddev>
        </noise>
      </ray>
      <plugin filename="libgazebo_ros_laser.so" name="summit_xl__front_laser_controller">
        <topicName>front_laser/scan</topicName>
        <frameName>/summit_xl__front_laser_link</frameName>
      </plugin>
    </sensor>
  </gazebo>
  <joint name="velodyne_base_mount_joint" type="fixed">
    <origin rpy="0 0 0" xyz="0.24457 0.362 0.2824"/>
    <parent link="summit_xl__base_link"/>
    <child link="velodyne_base_link"/>
  </joint>
  <link name="velodyne_base_link">
    <inertial>
      <mass value="0.83"/>
      <origin xyz="0 0 0.03585"/>
      <inertia ixx="0.000908059425" ixy="0" ixz="0" iyy="0.000908059425" iyz="0" izz="0.0011049624"/>
    </inertial>
    <visual>
      <geometry>
        <mesh filename="package://velodyne_description/meshes/VLP16_base_1.dae"/>
      </geometry>
    </visual>
    <visual>
      <geometry>
        <mesh filename="package://velodyne_description/meshes/VLP16_base_2.dae"/>
      </geometry>
    </visual>
    <collision>
      <origin rpy="0 0 0" xyz="0 0 0.03585"/>
      <geometry>
        <cylinder length="0.0717" radius="0.0516"/>
      </geometry>
    </collision>
  </link>
  <joint name="velodyne_base_scan_joint" type="fixed">
    <origin rpy="0 0 0" xyz="0 0 0.0377"/>
    <parent link="velodyne_base_link"/>
    <child link="velodyne"/>
  </joint>
  <link name="velodyne">
    <inertial>
      <mass value="0.01"/>
      <origin xyz="0 0 0"/>
      <inertia ixx="1e-7" ixy="0" ixz="0" iyy="1e-7" iyz="0" izz="1e-7"/>
    </inertial>
    <visual>
      <origin xyz="0 0 -0.0377"/>
      <geometry>
        <mesh filename="package://velodyne_description/meshes/VLP16_scan.dae"/>
      </geometry>
    </visual>
  </link>
  <!-- Gazebo requires the velodyne_gazebo_plugins package -->
  <gazebo reference="velodyne">
    <sensor name="velodyne-VLP16" type="ray">
      <pose>0 0 0 0 0 0</pose>
      <visualize>false</visualize>
      <update_rate>10</update_rate>
      <ray>
        <scan>
          <horizontal>
            <samples>440</samples>
            <resolution>1</resolution>
            <min_angle>-3.14159265359</min_angle>
            <max_angle>3.14159265359</max_angle>
          </horizontal>
          <vertical>
            <samples>16</samples>
            <resolution>1</resolution>
            <min_angle>-0.261799387799</min_angle>
            <max_angle> 0.261799387799</max_angle>
          </vertical>
        </scan>
        <range>
          <min>0.3</min>
          <max>131.0</max>
          <resolution>0.001</resolution>
        </range>
        <noise>
          <type>gaussian</type>
          <mean>0.0</mean>
          <stddev>0.0</stddev>
        </noise>
      </ray>
      <plugin filename="libgazebo_ros_velodyne_laser.so" name="gazebo_ros_laser_controller">
        <topicName>velodyne_points</topicName>
        <frameName>/velodyne</frameName>
        <min_range>0.9</min_range>
        <max_range>130.0</max_range>
        <gaussianNoise>0.008</gaussianNoise>
      </plugin>
    </sensor>
  </gazebo>
  <link name="summit_xl__rear_laser_link">
	</link>
  <joint name="summit_xl__rear_laser_joint" type="fixed">
    <parent link="summit_xl__base_link"/>
    <child link="summit_xl__rear_laser_link"/>
    <origin rpy="0 0 2.35619449019" xyz="-0.20957 -0.377 0.2024"/>
  </joint>
  <joint name="summit_xl__rear_laser_base_joint" type="fixed">
    <origin rpy="0 0 0" xyz="0.00 0 -0.05"/>
    <parent link="summit_xl__rear_laser_link"/>
    <child link="summit_xl__rear_laser_base_link"/>
  </joint>
  <link name="summit_xl__rear_laser_base_link">
    <collision>
      <origin rpy="0 0 0" xyz="0 0 0.0"/>
      <geometry>
        <box size="0.010 0.010 0.010"/>
      </geometry>
    </collision>
    <visual>
      <origin rpy="0 0 0" xyz="0 0 0.0"/>
      <geometry>
        <mesh filename="package://robotnik_sensors/meshes/hokuyo_ust_10lx.dae"/>
      </geometry>
    </visual>
    <inertial>
      <mass value="1e-5"/>
      <origin rpy="0 0 0" xyz="0 0 0"/>
      <inertia ixx="1e-6" ixy="0" ixz="0" iyy="1e-6" iyz="0" izz="1e-6"/>
    </inertial>
  </link>
  <gazebo reference="summit_xl__rear_laser_link">
    <sensor name="summit_xl__rear_laser_sensor" type="ray">
      <pose>0 0 0 0 0 0</pose>
      <visualize>false</visualize>
      <update_rate>40</update_rate>
      <ray>
        <scan>
          <horizontal>
            <samples>1081</samples>
            <resolution>1</resolution>
            <min_angle>-2.3562</min_angle>
            <max_angle>2.3562</max_angle>
          </horizontal>
        </scan>
        <range>
          <min>0.06</min>
          <max>10.0</max>
          <!-- resolution>0.004363323</resolution -->
          <resolution>0.004359297</resolution>
          <!-- resolution>0.001</resolution -->
        </range>
        <noise>
          <type>gaussian</type>
          <mean>0.0</mean>
          <stddev>0.01</stddev>
        </noise>
      </ray>
      <plugin filename="libgazebo_ros_laser.so" name="summit_xl__rear_laser_controller">
        <topicName>rear_laser/scan</topicName>
        <frameName>/summit_xl__rear_laser_link</frameName>
      </plugin>
    </sensor>
  </gazebo>
  <joint name="summit_xl__front_ptz_camera_joint" type="fixed">
    <axis xyz="0 1 0"/>
    <origin rpy="0 0 1.57079632679" xyz="-0.151 0.308 0.425"/>
    <parent link="summit_xl__base_link"/>
    <child link="summit_xl__front_ptz_camera_base_link"/>
  </joint>
  <link name="summit_xl__front_ptz_camera_base_link">
    <inertial>
      <origin rpy="0 0 0" xyz="0 0 0"/>
      <mass value="0.1"/>
      <origin rpy="0 0 0" xyz="0 0 0"/>
      <inertia ixx="0.1" ixy="0" ixz="0" iyy="0.1" iyz="0" izz="0.1"/>
    </inertial>
    <visual>
      <origin rpy="0 1.57079632679 0" xyz="0 0 0"/>
      <!-- to center the axis model -->
      <material name="axis_color">
        <color rgba="0.1 0.1 0.1 1"/>
      </material>
      <geometry>
        <mesh filename="package://robotnik_sensors/meshes/axis_m5013.dae" scale="1.0 1.0 1.0"/>
      </geometry>
    </visual>
    <collision>
      <origin rpy="0 1.57079632679 0" xyz="0.0 0.0 0"/>
      <geometry>
        <mesh filename="package://robotnik_sensors/meshes/axis_m5013.stl" scale="1.0 1.0 1.0"/>
      </geometry>
    </collision>
  </link>
  <joint name="summit_xl__front_ptz_camera_pan_joint" type="revolute">
    <axis xyz="1 0 0"/>
    <origin rpy="0 0 0" xyz="0.04 0.0 0.0"/>
    <!-- check the displacement -->
    <parent link="summit_xl__front_ptz_camera_base_link"/>
    <child link="summit_xl__front_ptz_camera_pan_link"/>
    <limit effort="100.0" lower="-3.1416" upper="3.1416" velocity="100.0"/>
    <joint_properties damping="0.1" friction="{ptz_joint_friction}"/>
  </joint>
  <link name="summit_xl__front_ptz_camera_pan_link">
    <inertial>
      <mass value="0.1"/>
      <origin rpy="0 0 0" xyz="0 0 0"/>
      <inertia ixx="0.1" ixy="0" ixz="0" iyy="0.1" iyz="0" izz="0.1"/>
    </inertial>
  </link>
  <transmission name="summit_xl__front_ptz_camera_pan_trans">
    <type>transmission_interface/SimpleTransmission</type>
    <joint name="summit_xl__front_ptz_camera_pan_joint">
      <hardwareInterface>hardware_interface/PositionJointInterface</hardwareInterface>
    </joint>
    <actuator name="summit_xl__front_ptz_camerapan_motor">
      <hardwareInterface>hardware_interface/PositionJointInterface</hardwareInterface>
      <mechanicalReduction>1.0</mechanicalReduction>
    </actuator>
  </transmission>
  <joint name="summit_xl__front_ptz_camera_tilt_joint" type="revolute">
    <axis xyz="0 -1 0"/>
    <origin rpy="0 -1.57079632679 0" xyz="0.0 0.0 0.0"/>
    <parent link="summit_xl__front_ptz_camera_pan_link"/>
    <child link="summit_xl__front_ptz_camera_tilt_link"/>
    <limit effort="100.0" lower="-1.5708" upper="1.5708" velocity="100.0"/>
    <joint_properties damping="0.1" friction="{ptz_joint_friction}"/>
  </joint>
  <link name="summit_xl__front_ptz_camera_tilt_link">
    <inertial>
      <mass value="0.1"/>
      <origin rpy="0 0 0" xyz="0 0 0"/>
      <inertia ixx="0.1" ixy="0" ixz="0" iyy="0.1" iyz="0" izz="0.1"/>
    </inertial>
  </link>
  <transmission name="summit_xl__front_ptz_camera_tilt_trans">
    <type>transmission_interface/SimpleTransmission</type>
    <joint name="summit_xl__front_ptz_camera_tilt_joint">
      <hardwareInterface>hardware_interface/PositionJointInterface</hardwareInterface>
    </joint>
    <actuator name="summit_xl__front_ptz_cameratilt_motor">
      <hardwareInterface>hardware_interface/PositionJointInterface</hardwareInterface>
      <mechanicalReduction>1.0</mechanicalReduction>
    </actuator>
  </transmission>
  <joint name="summit_xl__front_ptz_camera_frame_joint" type="fixed">
    <origin rpy="0 0 0" xyz="0 0 0"/>
    <parent link="summit_xl__front_ptz_camera_tilt_link"/>
    <child link="summit_xl__front_ptz_camera_frame_link"/>
  </joint>
  <link name="summit_xl__front_ptz_camera_frame_link">
    <inertial>
      <mass value="0.001"/>
      <origin xyz="0 0 0"/>
      <inertia ixx="0.0001" ixy="0.0" ixz="0.0" iyy="0.0001" iyz="0.0" izz="0.0001"/>
    </inertial>
  </link>
  <!-- Optical frame -->
  <joint name="summit_xl__front_ptz_camera_optical_joint" type="fixed">
    <origin rpy="-1.57079632679 0 -1.57079632679" xyz="0 0 0"/>
    <parent link="summit_xl__front_ptz_camera_frame_link"/>
    <child link="summit_xl__front_ptz_camera_optical_frame_link"/>
  </joint>
  <link name="summit_xl__front_ptz_camera_optical_frame_link">
    <inertial>
      <mass value="0.001"/>
      <origin xyz="0 0 0"/>
      <inertia ixx="0.0001" ixy="0.0" ixz="0.0" iyy="0.0001" iyz="0.0" izz="0.0001"/>
    </inertial>
  </link>
  <gazebo reference="summit_xl__front_ptz_camera_base_link">
    <material>Gazebo/FlatBlack</material>
  </gazebo>
  <gazebo reference="summit_xl__front_ptz_camera_frame_link">
    <!-- the image will be generated from this (${name}_frame) point of view, with the front being the X axis -->
    <sensor name="summit_xl__front_ptz_camera_sensor" type="camera">
      <update_rate>30.0</update_rate>
      <camera name="summit_xl__front_ptz_camera">
        <horizontal_fov>1.0471975512</horizontal_fov>
        <image>
          <format>R8G8B8</format>
          <width>640</width>
          <height>480</height>
        </image>
        <clip>
          <near>0.05</near>
          <far>8.0</far>
        </clip>
      </camera>
      <plugin filename="libgazebo_ros_camera.so" name="summit_xl__front_ptz_camera_controller">
        <cameraName>summit_xl__front_ptz_camera</cameraName>
        <alwaysOn>true</alwaysOn>
        <updateRate>0.0</updateRate>
        <cameraName>summit_xl__front_ptz_camera</cameraName>
        <imageTopicName>image_raw</imageTopicName>
        <cameraInfoTopicName>camera_info</cameraInfoTopicName>
        <frameName>summit_xl__front_ptz_camera_optical_frame_link</frameName>
        <!-- this is just which name the Image msg will have, it does not affect the simulation.
					     However must be set to the optical_frame,  -->
        <hackBaseline>0.07</hackBaseline>
        <distortionK1>0.0</distortionK1>
        <distortionK2>0.0</distortionK2>
        <distortionK3>0.0</distortionK3>
        <distortionT1>0.0</distortionT1>
        <distortionT2>0.0</distortionT2>
        <ignoreTfPrefix>1</ignoreTfPrefix>
      </plugin>
    </sensor>
  </gazebo>
  <!-- <xacro:sensor_axis_m5013 prefix="$(arg prefix)rear_ptz_camera" parent="$(arg prefix)base_link">
			<origin xyz="${rear_ptz_camera_offset_x} ${rear_ptz_camera_offset_y} ${rear_ptz_camera_offset_z}" rpy="${-PI/2} 0 ${PI}"/>
		</xacro:sensor_axis_m5013> -->
  <joint name="summit_xl__front_rgbd_camera_rgb_joint" type="fixed">
    <origin rpy="0 0 0" xyz="-0.012 0.324 0.23"/>
    <parent link="summit_xl__base_link"/>
    <child link="summit_xl__front_rgbd_camera_rgb_base_link"/>
  </joint>
  <link name="summit_xl__front_rgbd_camera_rgb_base_link">
    <inertial>
      <mass value="0.001"/>
      <origin xyz="0 0 0"/>
      <inertia ixx="0.0001" ixy="0.0" ixz="0.0" iyy="0.0001" iyz="0.0" izz="0.0001"/>
    </inertial>
  </link>
  <joint name="summit_xl__front_rgbd_camera_rgb_optical_joint" type="fixed">
    <origin rpy="-1.57079632679 0 -1.57079632679" xyz="0.0 0.0 0.0"/>
    <parent link="summit_xl__front_rgbd_camera_rgb_base_link"/>
    <child link="summit_xl__front_rgbd_camera_rgb_optical_frame"/>
  </joint>
  <link name="summit_xl__front_rgbd_camera_rgb_optical_frame">
    <!--inertial>
        <mass value="0.001" />
        <origin xyz="0 0 0" />
        <inertia ixx="0.0001" ixy="0.0" ixz="0.0"
          iyy="0.0001" iyz="0.0"
          izz="0.0001" />
      </inertial-->
  </link>
  <joint name="summit_xl__front_rgbd_camera_joint" type="fixed">
    <origin rpy="0.0 0 0" xyz="0.0 -0.0125 -0.015"/>
    <parent link="summit_xl__front_rgbd_camera_rgb_base_link"/>
    <child link="summit_xl__front_rgbd_camera_link"/>
  </joint>
  <link name="summit_xl__front_rgbd_camera_link">
    <visual>
      <origin rpy="0 0 0" xyz="0 0 0"/>
      <geometry>
        <mesh filename="package://robotnik_sensors/meshes/orbbec_astra.dae" scale="1.0 1.0 1.0"/>
      </geometry>
    </visual>
    <collision>
      <origin rpy="0 0 0" xyz="0.0 0.0 0.0"/>
      <!--geometry>
        <box size="0.0730 .2760 0.0720"/>
      </geometry-->
      <geometry>
        <mesh filename="package://robotnik_sensors/meshes/orbbec_astra.dae" scale="1.0 1.0 1.0"/>
      </geometry>
    </collision>
    <inertial>
      <!--mass value="0.01" />
        <origin xyz="0 0 0" />
        <inertia ixx="0.001" ixy="0.0" ixz="0.0"
          iyy="0.001" iyz="0.0"
          izz="0.001" /-->
      <mass value="0.564"/>
      <origin xyz="0 0 0"/>
      <inertia ixx="0.003881243" ixy="0.0" ixz="0.0" iyy="0.000498940" iyz="0.0" izz="0.003879257"/>
    </inertial>
  </link>
  <joint name="summit_xl__front_rgbd_camera_depth_joint" type="fixed">
    <origin rpy="0 0 0" xyz="0.0 0.025 0.0"/>
    <parent link="summit_xl__front_rgbd_camera_rgb_base_link"/>
    <child link="summit_xl__front_rgbd_camera_depth_frame"/>
  </joint>
  <link name="summit_xl__front_rgbd_camera_depth_frame">
    <!--inertial>
        <mass value="0.01" />
        <origin xyz="0 0 0" />
        <inertia ixx="0.001" ixy="0.0" ixz="0.0"
          iyy="0.001" iyz="0.0"
          izz="0.001" />
      </inertial-->
  </link>
  <joint name="summit_xl__front_rgbd_camera_depth_optical_joint" type="fixed">
    <origin rpy="-1.57079632679 0 -1.57079632679" xyz="0 0 0"/>
    <parent link="summit_xl__front_rgbd_camera_depth_frame"/>
    <child link="summit_xl__front_rgbd_camera_depth_optical_frame"/>
  </joint>
  <link name="summit_xl__front_rgbd_camera_depth_optical_frame">
    <!--inertial>
        <mass value="0.001" />
        <origin xyz="0 0 0" />
        <inertia ixx="0.0001" ixy="0.0" ixz="0.0"
          iyy="0.0001" iyz="0.0"
          izz="0.0001" />
      </inertial-->
  </link>
  <gazebo reference="summit_xl__front_rgbd_camera_rgb_base_link">
    <sensor name="summit_xl__front_rgbd_camera_depth_sensor" type="depth">
      <always_on>true</always_on>
      <update_rate>20.0</update_rate>
      <camera>
        <horizontal_fov>1.0471975512</horizontal_fov>
        <image>
          <format>R8G8B8</format>
          <width>640</width>
          <height>480</height>
        </image>
        <clip>
          <near>0.05</near>
          <far>3.5</far>
        </clip>
      </camera>
      <plugin filename="libgazebo_ros_openni_kinect.so" name="summit_xl__front_rgbd_camera_controller">
        <cameraName>front_rgbd_camera</cameraName>
        <alwaysOn>true</alwaysOn>
        <updateRate>10</updateRate>
        <imageTopicName>rgb/image_raw</imageTopicName>
        <depthImageTopicName>depth/image_raw</depthImageTopicName>
        <pointCloudTopicName>depth/points</pointCloudTopicName>
        <cameraInfoTopicName>rgb/camera_info</cameraInfoTopicName>
        <depthImageCameraInfoTopicName>depth/camera_info</depthImageCameraInfoTopicName>
        <frameName>/summit_xl__front_rgbd_camera_depth_optical_frame</frameName>
        <baseline>0.1</baseline>
        <distortion_k1>0.0</distortion_k1>
        <distortion_k2>0.0</distortion_k2>
        <distortion_k3>0.0</distortion_k3>
        <distortion_t1>0.0</distortion_t1>
        <distortion_t2>0.0</distortion_t2>
        <pointCloudCutoff>0.4</pointCloudCutoff>
      </plugin>
    </sensor>
  </gazebo>
  <!-- ANTENNA GPS -->
  <joint name="summit_xl__gps_joint" type="fixed">
    <axis xyz="0 1 0"/>
    <origin rpy="0 0 0" xyz="0.167 -0.365 0.302"/>
    <parent link="summit_xl__base_link"/>
    <child link="summit_xl__gps_base_link"/>
  </joint>
  <link name="summit_xl__gps_base_link">
    <inertial>
      <mass value="0.001"/>
      <origin rpy="0 0 0" xyz="0 0 0"/>
      <inertia ixx="0.0001" ixy="0" ixz="0" iyy="0.000001" iyz="0" izz="0.0001"/>
    </inertial>
    <visual>
      <origin rpy="0 0 0" xyz="0 0 0"/>
      <material name="gps_color">
        <color rgba="1 1 1 1"/>
      </material>
      <geometry>
        <mesh filename="package://robotnik_sensors/meshes/antenna_3GO16.stl" scale="1.0 1.0 1.0"/>
      </geometry>
    </visual>
    <collision>
      <origin rpy="0 0 0" xyz="0 0 0"/>
      <geometry>
        <mesh filename="package://robotnik_sensors/meshes/antenna_3GO16.stl" scale="1.0 1.0 1.0"/>
      </geometry>
    </collision>
  </link>
  <gazebo reference="summit_xl__gps_base_link">
    <material>Gazebo/White</material>
    <gravity>true</gravity>
  </gazebo>
  <gazebo>
    <plugin filename="libhector_gazebo_ros_gps.so" name="summit_xl__gps_controller">
      <alwaysOn>1</alwaysOn>
      <updateRate>5</updateRate>
      <bodyName>summit_xl__gps_base_link</bodyName>
      <!-- must be the link of the gps device, not the base_link or base_footprint -->
      <frameId>/summit_xl__gps_base_link</frameId>
      <topicName>fix</topicName>
      <!-- Robotnik position at Fuente del Jarro -->
      <referenceLatitude>39.5080331</referenceLatitude>
      <referenceLongitude>-0.4619816</referenceLongitude>
      <!-- To set heading in ENU orientation (degrees) -->
      <referenceHeading>90</referenceHeading>
      <velocityTopicName>fix_velocity</velocityTopicName>
      <drift>0.0 0.0 0.0</drift>
      <!--<drift>0.0001 0.0001 0.0001</drift>-->
      <!--<drift>0.3 0.3 0.3</drift>-->
      <gaussianNoise>0.1 0.1 0.1</gaussianNoise>
      <!--<gaussianNoise>0.00001 0.00001 0.00001</gaussianNoise>-->
      <velocityDrift>0.00001 0.00001 0.00001</velocityDrift>
      <!--<velocityGaussianNoise>0.1 0.1 0.1</velocityGaussianNoise>-->
      <velocityGaussianNoise>0.00001 0.00001 0.00001</velocityGaussianNoise>
    </plugin>
  </gazebo>
  <!-- Calling the Xacro files of the wam robot and barret hand, and adding the joint from the mobile robot and the arm -->
  <joint name="summit_xl_/wam/wam_fixed_joint" type="fixed">
    <parent link="summit_xl__base_link"/>
    <child link="summit_xl_/wam/base_link"/>
    <origin rpy="0 0 1.57079632679" xyz="0 0.14 0.405"/>
  </joint>
  <link name="summit_xl_/wam/base_link">
    <inertial>
      <origin xyz="0 0 0"/>
      <mass value="1"/>
      <inertia ixx="0.1" ixy="0" ixz="0" iyy="0.1" iyz="0" izz="0.1"/>
    </inertial>
    <visual>
      <material name="WAMGrey">
        <color rgba="0.7 0.7 0.7 0.0"/>
      </material>
      <geometry>
        <mesh filename="package://summit_xl_description/urdf/models/sw_meshes/base_link_fine.stl"/>
      </geometry>
    </visual>
    <collision>
      <geometry>
        <mesh filename="package://summit_xl_description/urdf/models/sw_meshes/base_link_convex.dae"/>
      </geometry>
    </collision>
  </link>
  <joint name="summit_xl_/wam/base_yaw_joint" type="revolute">
    <parent link="summit_xl_/wam/base_link"/>
    <child link="summit_xl_/wam/shoulder_yaw_link"/>
    <origin rpy="0 0 0" xyz="0 0 0.346"/>
    <axis xyz="0 0 1"/>
    <limit effort="100" lower="-2.6" upper="2.6" velocity="2.0"/>
    <!--limit effort 60-->
    <dynamics damping="1.98" friction="0"/>
  </joint>
  <gazebo reference="summit_xl_/wam/base_yaw_joint">
    <provideFeedback>true</provideFeedback>
    <implicitSpringDamper>true</implicitSpringDamper>
    <!--<kp>0.0</kp>[> CFM <]-->
    <!--<kd>0.0</kd>[> ERP <]-->
    <!--<cfmDamping>true</cfmDamping>-->
    <!--<dynamics damping="5.5" friction="1"/>-->
  </gazebo>
  <!-- <xacro:gazebo_reference name="${prefix}/shoulder_yaw_link"/> -->
  <link name="summit_xl_/wam/shoulder_yaw_link">
    <inertial>
      <origin xyz="-.00443422 -.00066489 -0.1289039 "/>
      <mass value="5.0"/>
      <inertia ixx=".13488033" ixy="-0.00012485" ixz="0.00213041" iyy=".09046330" iyz="-.00068555" izz=".11328369"/>
    </inertial>
    <visual>
      <material name="WAMGrey">
        <color rgba="0.7 0.7 0.7 1.0"/>
      </material>
      <geometry>
        <mesh filename="package://summit_xl_description/urdf/models/sw_meshes/shoulder_link_fine.stl"/>
      </geometry>
    </visual>
    <collision>
      <geometry>
        <mesh filename="package://summit_xl_description/urdf/models/sw_meshes/shoulder_link_convex_decomposition.dae"/>
      </geometry>
    </collision>
  </link>
  <joint name="summit_xl_/wam/shoulder_pitch_joint" type="revolute">
    <parent link="summit_xl_/wam/shoulder_yaw_link"/>
    <child link="summit_xl_/wam/shoulder_pitch_link"/>
    <origin rpy="-1.57079632679 0 0" xyz="0 0 0"/>
    <axis xyz="0 0 1"/>
    <limit effort="100" lower="-1.985" upper="1.985" velocity="2.0"/>
    <!--limit effort 60-->
    <dynamics damping="0.55" friction="0"/>
  </joint>
  <gazebo reference="summit_xl_/wam/shoulder_pitch_joint">
    <provideFeedback>true</provideFeedback>
    <implicitSpringDamper>true</implicitSpringDamper>
    <!--<kp>0.0</kp>[> CFM <]-->
    <!--<kd>0.0</kd>[> ERP <]-->
    <!--<cfmDamping>true</cfmDamping>-->
    <!--<dynamics damping="5.5" friction="1"/>-->
  </gazebo>
  <!-- <xacro:gazebo_reference name="${prefix}/shoulder_pitch_link"/> -->
  <link name="summit_xl_/wam/shoulder_pitch_link">
    <visual>
      <material name="WAMGrey">
        <color rgba="0.7 0.7 0.7 1.0"/>
      </material>
      <geometry>
        <mesh filename="package://summit_xl_description/urdf/models/sw_meshes/shoulder_pitch_link_fine.stl"/>
      </geometry>
    </visual>
    <inertial>
      <origin xyz="-.00236981 -.01542114 .03105614 "/>
      <mass value="3.87493756"/>
      <inertia ixx="0.02140958" ixy="-0.00002461" ixz="0.00027172" iyy="0.015589060" iyz="0.0018192" izz="0.01377875"/>
    </inertial>
    <collision>
      <geometry>
        <mesh filename="package://summit_xl_description/urdf/models/sw_meshes/shoulder_pitch_link_convex.dae"/>
      </geometry>
    </collision>
  </link>
  <joint name="summit_xl_/wam/shoulder_yaw_joint" type="revolute">
    <parent link="summit_xl_/wam/shoulder_pitch_link"/>
    <child link="summit_xl_/wam/upper_arm_link"/>
    <origin rpy="1.57079632679 0 0" xyz="0 0 0"/>
    <axis xyz="0 0 1"/>
    <limit effort="100" lower="-2.8" upper="2.8" velocity="2.0"/>
    <!--limit effort 45-->
    <dynamics damping="1.65" friction="0"/>
  </joint>
  <gazebo reference="summit_xl_/wam/shoulder_yaw_joint">
    <provideFeedback>true</provideFeedback>
    <implicitSpringDamper>true</implicitSpringDamper>
    <!--<kp>0.0</kp>[> CFM <]-->
    <!--<kd>0.0</kd>[> ERP <]-->
    <!--<cfmDamping>true</cfmDamping>-->
    <!--<dynamics damping="5.5" friction="1"/>-->
  </gazebo>
  <!-- <xacro:gazebo_reference name="${prefix}/upper_arm_link"/> -->
  <link name="summit_xl_/wam/upper_arm_link">
    <inertial>
      <origin xyz="0.00683258580000000 0.000033090000000 0.392492300000000"/>
      <mass value="2.20228141"/>
      <inertia ixx=".05911077" ixy="-0.00000738" ixz="-0.00249612" iyy="0.05927043" iyz="0.00001767" izz="0.0032455"/>
    </inertial>
    <visual>
      <material name="WAMGrey">
        <color rgba="0.7 0.7 0.7 1.0"/>
      </material>
      <geometry>
        <mesh filename="package://summit_xl_description/urdf/models/sw_meshes/upper_arm_link_fine.stl"/>
      </geometry>
    </visual>
    <collision>
      <geometry>
        <mesh filename="package://summit_xl_description/urdf/models/sw_meshes/upper_arm_link_convex_decomposition.dae"/>
      </geometry>
    </collision>
  </link>
  <joint name="summit_xl_/wam/elbow_pitch_joint" type="revolute">
    <parent link="summit_xl_/wam/upper_arm_link"/>
    <child link="summit_xl_/wam/forearm_link"/>
    <origin rpy="-1.57079632679 0 0" xyz="0.045 0 0.55"/>
    <axis xyz="0 0 1"/>
    <limit effort="100" lower="-0.9" upper="3.14159265359" velocity="2.00"/>
    <!--limit effort 30-->
    <dynamics damping="0.88" friction="0"/>
  </joint>
  <gazebo reference="summit_xl_/wam/elbow_pitch_joint">
    <provideFeedback>true</provideFeedback>
    <implicitSpringDamper>true</implicitSpringDamper>
    <!--<kp>0.0</kp>[> CFM <]-->
    <!--<kd>0.0</kd>[> ERP <]-->
    <!--<cfmDamping>true</cfmDamping>-->
    <!--<dynamics damping="5.5" friction="1"/>-->
  </gazebo>
  <!-- <xacro:gazebo_reference name="${prefix}/forearm_link"/> -->
  <link name="summit_xl_/wam/forearm_link">
    <inertial>
      <mass value="0.50016804"/>
      <origin rpy="0 0 0" xyz="-0.04001488 -.14271662 -.00022942 "/>
      <inertia ixx="0.01491672" ixy="0.001506040000000" ixz="0.000017410000000" iyy="0.002944630000000" iyz="0.000021090000000" izz="0.014829880000000"/>
    </inertial>
    <visual>
      <material name="WAMGrey">
        <color rgba="0.7 0.7 0.7 1.0"/>
      </material>
      <geometry>
        <mesh filename="package://summit_xl_description/urdf/models/sw_meshes/elbow_link_fine.stl"/>
      </geometry>
    </visual>
    <collision>
      <geometry>
        <mesh filename="package://summit_xl_description/urdf/models/sw_meshes/elbow_link_convex.dae"/>
      </geometry>
    </collision>
    <visual>
      <material name="WAMGrey">
        <color rgba="0.7 0.7 0.7 1.0"/>
      </material>
      <origin rpy="1.57079632679 0 0" xyz="-0.045 -0.0730 0"/>
      <geometry>
        <mesh filename="package://summit_xl_description/urdf/models/sw_meshes/forearm_link_fine.stl"/>
      </geometry>
    </visual>
    <collision>
      <origin rpy="1.57079632679 0 0" xyz="-0.045 -0.0730 0"/>
      <geometry>
        <mesh filename="package://summit_xl_description/urdf/models/sw_meshes/forearm_link_convex_decomposition.dae"/>
      </geometry>
    </collision>
  </link>
  <joint name="summit_xl_/wam/wrist_yaw_joint" type="revolute">
    <parent link="summit_xl_/wam/forearm_link"/>
    <child link="summit_xl_/wam/wrist_yaw_link"/>
    <origin rpy="1.57079632679 0 0" xyz="-0.045 -0.3 0"/>
    <axis xyz="0 0 1"/>
    <limit effort="100" lower="-4.55" upper="1.25" velocity="2.0"/>
    <!--limit effort 10-->
    <dynamics damping="0.55" friction="0"/>
  </joint>
  <gazebo reference="summit_xl_/wam/wrist_yaw_joint">
    <provideFeedback>true</provideFeedback>
    <implicitSpringDamper>true</implicitSpringDamper>
    <!--<kp>0.0</kp>[> CFM <]-->
    <!--<kd>0.0</kd>[> ERP <]-->
    <!--<cfmDamping>true</cfmDamping>-->
    <!--<dynamics damping="5.5" friction="1"/>-->
  </gazebo>
  <!-- <xacro:gazebo_reference name="${prefix}/wrist_yaw_link"/> -->
  <link name="summit_xl_/wam/wrist_yaw_link">
    <inertial>
      <origin xyz="0.00008921 0.00435824 -0.00511217 "/>
      <mass value="1.05376019"/>
      <inertia ixx="0.00005029" ixy="0.00000020" ixz="0.00007582" iyy="0.00007582" iyz="-0.00000359" izz="0.00006270"/>
    </inertial>
    <visual>
      <material name="WAMGrey">
        <color rgba="0.7 0.7 0.7 1.0"/>
      </material>
      <origin rpy="0 0 0" xyz="0 0 0"/>
      <geometry>
        <mesh filename="package://summit_xl_description/urdf/models/sw_meshes/wrist_yaw_link_fine.stl"/>
      </geometry>
    </visual>
    <collision>
      <origin rpy="0 0 0" xyz="0 0 0"/>
      <geometry>
        <mesh filename="package://summit_xl_description/urdf/models/sw_meshes/wrist_yaw_link_convex_decomposition.dae"/>
      </geometry>
    </collision>
  </link>
  <joint name="summit_xl_/wam/wrist_pitch_joint" type="revolute">
    <parent link="summit_xl_/wam/wrist_yaw_link"/>
    <child link="summit_xl_/wam/wrist_pitch_link"/>
    <origin rpy="-1.57079632679 0 0" xyz="0 0 0"/>
    <axis xyz="0 0 1"/>
    <limit effort="100" lower="-1.5707" upper="1.5707" velocity="2.00"/>
    <!--limit effort 10-->
    <dynamics damping="0.11" friction="0"/>
  </joint>
  <gazebo reference="summit_xl_/wam/wrist_pitch_joint">
    <provideFeedback>true</provideFeedback>
    <implicitSpringDamper>true</implicitSpringDamper>
    <!--<kp>0.0</kp>[> CFM <]-->
    <!--<kd>0.0</kd>[> ERP <]-->
    <!--<cfmDamping>true</cfmDamping>-->
    <!--<dynamics damping="5.5" friction="1"/>-->
  </gazebo>
  <!-- <xacro:gazebo_reference name="${prefix}/wrist_pitch_link"/> -->
  <link name="summit_xl_/wam/wrist_pitch_link">
    <inertial>
      <origin rpy="0 0 0" xyz="-0.00012262 -0.02468336 -0.01703194 "/>
      <mass value="0.51797364"/>
      <inertia ixx="0.00055516" ixy="0.00000061" ixz="-0.00000074" iyy="0.00024367" iyz="-0.00004590" izz="0.00045358"/>
    </inertial>
    <visual>
      <material name="WAMGrey">
        <color rgba="0.7 0.7 0.7 1.0"/>
      </material>
      <geometry>
        <mesh filename="package://summit_xl_description/urdf/models/sw_meshes/wrist_pitch_link_fine.stl"/>
      </geometry>
    </visual>
    <collision>
      <geometry>
        <mesh filename="package://summit_xl_description/urdf/models/sw_meshes/wrist_pitch_link_convex_decomposition.dae"/>
      </geometry>
    </collision>
  </link>
  <joint name="summit_xl_/wam/palm_yaw_joint" type="revolute">
    <parent link="summit_xl_/wam/wrist_pitch_link"/>
    <child link="summit_xl_/wam/wrist_palm_link"/>
    <origin rpy="1.57079632679 0 0" xyz="0 0 0"/>
    <axis xyz="0 0 1"/>
    <limit effort="100" lower="-3.0" upper="3.0" velocity="2.00"/>
    <!-- 2.95 is a limit taken in from 3 due to saftey and differences between arms. -->
    <!--limit effort 10-->
    <dynamics damping="0.11" friction="0"/>
  </joint>
  <gazebo reference="summit_xl_/wam/palm_yaw_joint">
    <provideFeedback>true</provideFeedback>
    <implicitSpringDamper>true</implicitSpringDamper>
    <!--<kp>0.0</kp>[> CFM <]-->
    <!--<kd>0.0</kd>[> ERP <]-->
    <!--<cfmDamping>true</cfmDamping>-->
    <!--<dynamics damping="5.5" friction="1"/>-->
  </gazebo>
  <!-- <xacro:gazebo_reference name="${prefix}/wrist_palm_link"/> -->
  <link name="summit_xl_/wam/wrist_palm_link">
    <inertial>
      <origin rpy="0 0 0" xyz="0.0 0.0 0.055"/>
      <mass value="0.08286134"/>
      <inertia ixx="0.00010859" ixy="0.00000000" ixz="-0.00000000" iyy="0.00020683" iyz="-0.0000000" izz="0.00010851"/>
    </inertial>
    <visual>
      <material name="WAMGrey">
        <color rgba="0.7 0.7 0.7 1.0"/>
      </material>
      <origin rpy="0 0 0" xyz="0 0 0"/>
      <geometry>
        <mesh filename="package://summit_xl_description/urdf/models/sw_meshes/wrist_palm_link_fine.stl"/>
      </geometry>
    </visual>
    <collision>
      <origin rpy="0 0 0" xyz="0 0 0"/>
      <geometry>
        <mesh filename="package://summit_xl_description/urdf/models/sw_meshes/wrist_palm_link_convex.dae"/>
      </geometry>
    </collision>
  </link>
  <!-- <xacro:wam_wrist_palm_stump prefix="${prefix}"/> -->
  <!-- Joint 1 transmission and motor -->
  <transmission name="summit_xl_/wam/base_yaw_joint_trans">
    <type>transmission_interface/SimpleTransmission</type>
    <joint name="summit_xl_/wam/base_yaw_joint">
      <!--https://sir.upc.edu/projects/rostutorials/10-gazebo_control_tutorial/index.html#ros-control-interfaces-->
      <hardwareInterface>hardware_interface/EffortJointInterface</hardwareInterface>
    </joint>
    <actuator name="summit_xl_/wam/base_yaw_joint_motor">
      <mechanicalReduction>1</mechanicalReduction>
      <hardwareInterface>hardware_interface/EffortJointInterface</hardwareInterface>
    </actuator>
  </transmission>
  <!-- Joint 2 transmission and motor -->
  <transmission name="summit_xl_/wam/shoulder_pitch_joint_trans">
    <type>transmission_interface/SimpleTransmission</type>
    <joint name="summit_xl_/wam/shoulder_pitch_joint">
      <hardwareInterface>hardware_interface/EffortJointInterface</hardwareInterface>
    </joint>
    <actuator name="summit_xl_/wam/shoulder_pitch_joint_motor">
      <mechanicalReduction>1</mechanicalReduction>
      <hardwareInterface>hardware_interface/EffortJointInterface</hardwareInterface>
    </actuator>
  </transmission>
  <!-- Joint 3 transmission and motor -->
  <transmission name="summit_xl_/wam/shoulder_yaw_joint_trans">
    <type>transmission_interface/SimpleTransmission</type>
    <joint name="summit_xl_/wam/shoulder_yaw_joint">
      <hardwareInterface>hardware_interface/EffortJointInterface</hardwareInterface>
    </joint>
    <actuator name="summit_xl_/wam/shoulder_yaw_joint_motor">
      <mechanicalReduction>1</mechanicalReduction>
      <hardwareInterface>hardware_interface/EffortJointInterface</hardwareInterface>
    </actuator>
  </transmission>
  <!-- Joint 4 transmission and motor -->
  <transmission name="summit_xl_/wam/elbow_pitch_joint_trans">
    <type>transmission_interface/SimpleTransmission</type>
    <joint name="summit_xl_/wam/elbow_pitch_joint">
      <hardwareInterface>hardware_interface/EffortJointInterface</hardwareInterface>
    </joint>
    <actuator name="summit_xl_/wam/elbow_pitch_joint_motor">
      <mechanicalReduction>1</mechanicalReduction>
      <hardwareInterface>hardware_interface/EffortJointInterface</hardwareInterface>
    </actuator>
  </transmission>
  <!-- Joint 5 transmission and motor -->
  <transmission name="summit_xl_/wam/wrist_yaw_joint_trans">
    <type>transmission_interface/SimpleTransmission</type>
    <joint name="summit_xl_/wam/wrist_yaw_joint">
      <hardwareInterface>hardware_interface/EffortJointInterface</hardwareInterface>
    </joint>
    <actuator name="summit_xl_/wam/wrist_yaw_joint_motor">
      <mechanicalReduction>1</mechanicalReduction>
      <hardwareInterface>hardware_interface/EffortJointInterface</hardwareInterface>
    </actuator>
  </transmission>
  <!-- Joint 6 transmission and motor -->
  <transmission name="summit_xl_/wam/wrist_pitch_joint_trans">
    <type>transmission_interface/SimpleTransmission</type>
    <joint name="summit_xl_/wam/wrist_pitch_joint">
      <hardwareInterface>hardware_interface/EffortJointInterface</hardwareInterface>
    </joint>
    <actuator name="summit_xl_/wam/wrist_pitch_joint_motor">
      <mechanicalReduction>1</mechanicalReduction>
      <hardwareInterface>hardware_interface/EffortJointInterface</hardwareInterface>
    </actuator>
  </transmission>
  <!--Joint 7 transmission and motor -->
  <transmission name="summit_xl_/wam/palm_yaw_joint_trans">
    <type>transmission_interface/SimpleTransmission</type>
    <joint name="summit_xl_/wam/palm_yaw_joint">
      <hardwareInterface>hardware_interface/EffortJointInterface</hardwareInterface>
    </joint>
    <actuator name="summit_xl_/wam/palm_yaw_joint_motor">
      <mechanicalReduction>1</mechanicalReduction>
      <hardwareInterface>hardware_interface/EffortJointInterface</hardwareInterface>
    </actuator>
  </transmission>
  <joint name="summit_xl_/wam/bhand/bhand_base_joint" type="fixed">
    <parent link="summit_xl_/wam/wrist_palm_link"/>
    <child link="summit_xl_/wam/bhand/bhand_palm_link"/>
    <origin rpy="0 0 3.14159265359" xyz="0 0 0.06"/>
  </joint>
  <!-- <gazebo reference="${prefix}/bhand_palm_link">
      <xacro:gz_hand_link collide="${collision}"/>
    </gazebo> -->
  <link name="summit_xl_/wam/bhand/bhand_palm_link">
    <inertial>
      <origin xyz="-5.1098e-005 0.0050433 0.036671"/>
      <mass value="0.50573"/>
      <inertia ixx="3.8374e-005" ixy="-5.604e-008" ixz="-4.2034e-005" iyy="0.00022405" iyz="1.3283e-007" izz="0.00020045"/>
    </inertial>
    <visual>
      <material name="WAMGrey">
        <color rgba="0.9 0.9 0.9 0.0"/>
      </material>
      <geometry>
        <mesh filename="package://summit_xl_description/urdf/models/sw_meshes/bhand/bhand_palm_fine.stl"/>
      </geometry>
    </visual>
    <collision>
      <geometry>
        <mesh filename="package://summit_xl_description/urdf/models/sw_meshes/bhand/bhand_palm_link_convex_decomposition.dae"/>
      </geometry>
    </collision>
  </link>
  <joint name="summit_xl_/wam/bhand/bhand_palm_surface_joint" type="fixed">
    <parent link="summit_xl_/wam/bhand/bhand_palm_link"/>
    <child link="summit_xl_/wam/bhand/bhand_palm_surface_link"/>
    <origin rpy="0 0 0" xyz="0 0 0.08"/>
    <limit effort="100" lower="0" upper="3.14159265359" velocity="5.0"/>
    <dynamics damping="0.11" friction="0"/>
  </joint>
  <!-- <gazebo reference="${prefix}/bhand_palm_surface_link">
      <xacro:gz_hand_link collide="${collision}"/>
    </gazebo> -->
  <link name="summit_xl_/wam/bhand/bhand_palm_surface_link">
    <inertial>
      <mass value="0.000001"/>
      <inertia ixx="0.000001" ixy="0.0" ixz="0.0" iyy="0.000001" iyz="0.0" izz="0.000001"/>
    </inertial>
  </link>
  <joint name="summit_xl_/wam/bhand/bhand_grasp_joint" type="fixed">
    <parent link="summit_xl_/wam/bhand/bhand_palm_link"/>
    <child link="summit_xl_/wam/bhand/bhand_grasp_link"/>
    <origin rpy="0 0 0" xyz="0 0 0.12"/>
    <limit effort="100" lower="0" upper="3.14159265359" velocity="5.0"/>
    <dynamics damping="0.11" friction="0"/>
  </joint>
  <!-- <gazebo reference="${prefix}/bhand_grasp_link">
      <xacro:gz_hand_link collide="${collision}"/>
    </gazebo> -->
  <link name="summit_xl_/wam/bhand/bhand_grasp_link">
    <inertial>
      <mass value="0.000001"/>
      <inertia ixx="0.000001" ixy="0.0" ixz="0.0" iyy="0.000001" iyz="0.0" izz="0.000001"/>
    </inertial>
  </link>
  <joint name="summit_xl_/wam/bhand/finger_1/prox_joint" type="revolute">
    <parent link="summit_xl_/wam/bhand/bhand_palm_link"/>
    <child link="summit_xl_/wam/bhand/finger_1/prox_link"/>
    <origin rpy="0 0 -1.57079632679" xyz="-0.025 0.0 0.0415"/>
    <axis xyz="0 0 -1"/>
    <limit effort="100" lower="0" upper="3.14159265359" velocity="5.0"/>
    <dynamics damping="0.11" friction="0"/>
  </joint>
  <gazebo reference="summit_xl_/wam/bhand/finger_1/prox_joint">
    <provideFeedback>true</provideFeedback>
    <implicitSpringDamper>true</implicitSpringDamper>
    <!--<kp>0.0</kp>[> CFM <]-->
    <!--<kd>0.0</kd>[> ERP <]-->
    <!--<cfmDamping>true</cfmDamping>-->
    <!--<dynamics damping="5.5" friction="1"/>-->
  </gazebo>
  <gazebo reference="summit_xl_/wam/bhand/finger_1/prox_link">
    <mu1>0.8</mu1>
    <mu2>0.8</mu2>
    <selfCollide>true</selfCollide>
  </gazebo>
  <link name="summit_xl_/wam/bhand/finger_1/prox_link">
    <inertial>
      <origin xyz="0.023133 0.00078642 0.00052792"/>
      <mass value="0.14109"/>
      <inertia ixx="4.872e-006" ixy="1.7103e-006" ixz="3.4041e-008" iyy="7.6588e-005" iyz="2.3133e-008" izz="7.7733e-005"/>
    </inertial>
    <visual>
      <material name="WAMGrey">
        <color rgba="0.9 0.9 0.9 0.0"/>
      </material>
      <geometry>
        <mesh filename="package://summit_xl_description/urdf/models/sw_meshes/bhand/bhand_finger_prox_link_fine.stl"/>
      </geometry>
    </visual>
    <collision>
      <geometry>
        <mesh filename="package://summit_xl_description/urdf/models/sw_meshes/bhand/bhand_finger_prox_link_convex_decomposition.dae"/>
      </geometry>
    </collision>
  </link>
  <joint name="summit_xl_/wam/bhand/finger_1/med_joint" type="revolute">
    <parent link="summit_xl_/wam/bhand/finger_1/prox_link"/>
    <child link="summit_xl_/wam/bhand/finger_1/med_link"/>
    <origin rpy="1.57079632679 0 0" xyz="0.05 0.0 0.03390"/>
    <axis xyz="0 0 1"/>
    <limit effort="100" lower="0" upper="2.44346095279" velocity="5.00"/>
    <dynamics damping="0.11" friction="0"/>
  </joint>
  <gazebo reference="summit_xl_/wam/bhand/finger_1/med_joint">
    <provideFeedback>true</provideFeedback>
    <implicitSpringDamper>true</implicitSpringDamper>
    <!--<kp>0.0</kp>[> CFM <]-->
    <!--<kd>0.0</kd>[> ERP <]-->
    <!--<cfmDamping>true</cfmDamping>-->
    <!--<dynamics damping="5.5" friction="1"/>-->
  </gazebo>
  <gazebo reference="summit_xl_/wam/bhand/finger_1/med_link">
    <mu1>0.8</mu1>
    <mu2>0.8</mu2>
    <selfCollide>true</selfCollide>
  </gazebo>
  <link name="summit_xl_/wam/bhand/finger_1/med_link">
    <inertial>
      <origin xyz="0.023133 0.00078642 0.00052792"/>
      <mass value="0.062139"/>
      <inertia ixx="4.872e-006" ixy="1.7103e-006" ixz="3.4041e-008" iyy="7.6588e-005" iyz="2.3133e-008" izz="7.7733e-005"/>
    </inertial>
    <visual>
      <material name="WAMGrey">
        <color rgba="0.9 0.9 0.9 0.0"/>
      </material>
      <geometry>
        <mesh filename="package://summit_xl_description/urdf/models/sw_meshes/bhand/bhand_finger_med_link_fine.stl"/>
      </geometry>
    </visual>
    <collision>
      <geometry>
        <mesh filename="package://summit_xl_description/urdf/models/sw_meshes/bhand/bhand_finger_med_link_convex.dae"/>
      </geometry>
    </collision>
  </link>
  <joint name="summit_xl_/wam/bhand/finger_1/dist_joint" type="revolute">
    <parent link="summit_xl_/wam/bhand/finger_1/med_link"/>
    <child link="summit_xl_/wam/bhand/finger_1/dist_link"/>
    <origin rpy="0 0 0.785398163397" xyz="0.06994 0.003 0.0"/>
    <axis xyz="0 0 1"/>
    <limit effort="100" lower="0" upper="0.837758040957" velocity="5.00"/>
    <dynamics damping="0.11" friction="0"/>
  </joint>
  <gazebo reference="summit_xl_/wam/bhand/finger_1/dist_joint">
    <provideFeedback>true</provideFeedback>
    <implicitSpringDamper>true</implicitSpringDamper>
    <!--<kp>0.0</kp>[> CFM <]-->
    <!--<kd>0.0</kd>[> ERP <]-->
    <!--<cfmDamping>true</cfmDamping>-->
    <!--<dynamics damping="5.5" friction="1"/>-->
  </gazebo>
  <gazebo reference="summit_xl_/wam/bhand/finger_1/dist_link">
    <mu1>0.8</mu1>
    <mu2>0.8</mu2>
    <selfCollide>true</selfCollide>
  </gazebo>
  <link name="summit_xl_/wam/bhand/finger_1/dist_link">
    <inertial>
      <origin rpy="0 0 0" xyz="0.022825 0.0010491 0.0004203"/>
      <mass value="0.041377"/>
      <inertia ixx="3.1582e-006" ixy="1.4308e-006" ixz="1.0106e-007" iyy="3.8376e-005" iyz="0" izz="3.7275e-005"/>
    </inertial>
    <visual>
      <origin rpy="0 0 -0.785398163397"/>
      <material name="WAMGrey">
        <color rgba="0.9 0.9 0.9 0.0"/>
      </material>
      <geometry>
        <mesh filename="package://summit_xl_description/urdf/models/sw_meshes/bhand/bhand_finger_dist_link_fine.stl"/>
      </geometry>
    </visual>
    <collision>
      <origin rpy="0 0 -0.785398163397"/>
      <geometry>
        <mesh filename="package://summit_xl_description/urdf/models/sw_meshes/bhand/bhand_finger_dist_link_convex.dae"/>
      </geometry>
    </collision>
  </link>
  <joint name="summit_xl_/wam/bhand/finger_1/tip_joint" type="fixed">
    <parent link="summit_xl_/wam/bhand/finger_1/dist_link"/>
    <child link="summit_xl_/wam/bhand/finger_1/tip_link"/>
    <origin rpy="0 0 0" xyz="0.05 0.0 0.0"/>
  </joint>
  <!-- <gazebo reference="${prefix}/tip_link">
      <xacro:gz_hand_link collide="${collision}"/>
    </gazebo> -->
  <link name="summit_xl_/wam/bhand/finger_1/tip_link">
    <inertial>
      <mass value="1E-6"/>
      <inertia ixx="1E-6" ixy="0" ixz="0" iyy="1E-6" iyz="0" izz="1E-6"/>
    </inertial>
  </link>
  <joint name="summit_xl_/wam/bhand/finger_2/prox_joint" type="revolute">
    <parent link="summit_xl_/wam/bhand/bhand_palm_link"/>
    <child link="summit_xl_/wam/bhand/finger_2/prox_link"/>
    <origin rpy="0 0 -1.57079632679" xyz="0.025 0.0 0.0415"/>
    <axis xyz="0 0 1"/>
    <limit effort="100" lower="0" upper="3.14159265359" velocity="5.0"/>
    <dynamics damping="0.11" friction="0"/>
  </joint>
  <gazebo reference="summit_xl_/wam/bhand/finger_2/prox_joint">
    <provideFeedback>true</provideFeedback>
    <implicitSpringDamper>true</implicitSpringDamper>
    <!--<kp>0.0</kp>[> CFM <]-->
    <!--<kd>0.0</kd>[> ERP <]-->
    <!--<cfmDamping>true</cfmDamping>-->
    <!--<dynamics damping="5.5" friction="1"/>-->
  </gazebo>
  <gazebo reference="summit_xl_/wam/bhand/finger_2/prox_link">
    <mu1>0.8</mu1>
    <mu2>0.8</mu2>
    <selfCollide>true</selfCollide>
  </gazebo>
  <link name="summit_xl_/wam/bhand/finger_2/prox_link">
    <inertial>
      <origin xyz="0.023133 0.00078642 0.00052792"/>
      <mass value="0.14109"/>
      <inertia ixx="4.872e-006" ixy="1.7103e-006" ixz="3.4041e-008" iyy="7.6588e-005" iyz="2.3133e-008" izz="7.7733e-005"/>
    </inertial>
    <visual>
      <material name="WAMGrey">
        <color rgba="0.9 0.9 0.9 0.0"/>
      </material>
      <geometry>
        <mesh filename="package://summit_xl_description/urdf/models/sw_meshes/bhand/bhand_finger_prox_link_fine.stl"/>
      </geometry>
    </visual>
    <collision>
      <geometry>
        <mesh filename="package://summit_xl_description/urdf/models/sw_meshes/bhand/bhand_finger_prox_link_convex_decomposition.dae"/>
      </geometry>
    </collision>
  </link>
  <joint name="summit_xl_/wam/bhand/finger_2/med_joint" type="revolute">
    <parent link="summit_xl_/wam/bhand/finger_2/prox_link"/>
    <child link="summit_xl_/wam/bhand/finger_2/med_link"/>
    <origin rpy="1.57079632679 0 0" xyz="0.05 0.0 0.03390"/>
    <axis xyz="0 0 1"/>
    <limit effort="100" lower="0" upper="2.44346095279" velocity="5.00"/>
    <dynamics damping="0.11" friction="0"/>
  </joint>
  <gazebo reference="summit_xl_/wam/bhand/finger_2/med_joint">
    <provideFeedback>true</provideFeedback>
    <implicitSpringDamper>true</implicitSpringDamper>
    <!--<kp>0.0</kp>[> CFM <]-->
    <!--<kd>0.0</kd>[> ERP <]-->
    <!--<cfmDamping>true</cfmDamping>-->
    <!--<dynamics damping="5.5" friction="1"/>-->
  </gazebo>
  <gazebo reference="summit_xl_/wam/bhand/finger_2/med_link">
    <mu1>0.8</mu1>
    <mu2>0.8</mu2>
    <selfCollide>true</selfCollide>
  </gazebo>
  <link name="summit_xl_/wam/bhand/finger_2/med_link">
    <inertial>
      <origin xyz="0.023133 0.00078642 0.00052792"/>
      <mass value="0.062139"/>
      <inertia ixx="4.872e-006" ixy="1.7103e-006" ixz="3.4041e-008" iyy="7.6588e-005" iyz="2.3133e-008" izz="7.7733e-005"/>
    </inertial>
    <visual>
      <material name="WAMGrey">
        <color rgba="0.9 0.9 0.9 0.0"/>
      </material>
      <geometry>
        <mesh filename="package://summit_xl_description/urdf/models/sw_meshes/bhand/bhand_finger_med_link_fine.stl"/>
      </geometry>
    </visual>
    <collision>
      <geometry>
        <mesh filename="package://summit_xl_description/urdf/models/sw_meshes/bhand/bhand_finger_med_link_convex.dae"/>
      </geometry>
    </collision>
  </link>
  <joint name="summit_xl_/wam/bhand/finger_2/dist_joint" type="revolute">
    <parent link="summit_xl_/wam/bhand/finger_2/med_link"/>
    <child link="summit_xl_/wam/bhand/finger_2/dist_link"/>
    <origin rpy="0 0 0.785398163397" xyz="0.06994 0.003 0.0"/>
    <axis xyz="0 0 1"/>
    <limit effort="100" lower="0" upper="0.837758040957" velocity="5.00"/>
    <dynamics damping="0.11" friction="0"/>
  </joint>
  <gazebo reference="summit_xl_/wam/bhand/finger_2/dist_joint">
    <provideFeedback>true</provideFeedback>
    <implicitSpringDamper>true</implicitSpringDamper>
    <!--<kp>0.0</kp>[> CFM <]-->
    <!--<kd>0.0</kd>[> ERP <]-->
    <!--<cfmDamping>true</cfmDamping>-->
    <!--<dynamics damping="5.5" friction="1"/>-->
  </gazebo>
  <gazebo reference="summit_xl_/wam/bhand/finger_2/dist_link">
    <mu1>0.8</mu1>
    <mu2>0.8</mu2>
    <selfCollide>true</selfCollide>
  </gazebo>
  <link name="summit_xl_/wam/bhand/finger_2/dist_link">
    <inertial>
      <origin rpy="0 0 0" xyz="0.022825 0.0010491 0.0004203"/>
      <mass value="0.041377"/>
      <inertia ixx="3.1582e-006" ixy="1.4308e-006" ixz="1.0106e-007" iyy="3.8376e-005" iyz="0" izz="3.7275e-005"/>
    </inertial>
    <visual>
      <origin rpy="0 0 -0.785398163397"/>
      <material name="WAMGrey">
        <color rgba="0.9 0.9 0.9 0.0"/>
      </material>
      <geometry>
        <mesh filename="package://summit_xl_description/urdf/models/sw_meshes/bhand/bhand_finger_dist_link_fine.stl"/>
      </geometry>
    </visual>
    <collision>
      <origin rpy="0 0 -0.785398163397"/>
      <geometry>
        <mesh filename="package://summit_xl_description/urdf/models/sw_meshes/bhand/bhand_finger_dist_link_convex.dae"/>
      </geometry>
    </collision>
  </link>
  <joint name="summit_xl_/wam/bhand/finger_2/tip_joint" type="fixed">
    <parent link="summit_xl_/wam/bhand/finger_2/dist_link"/>
    <child link="summit_xl_/wam/bhand/finger_2/tip_link"/>
    <origin rpy="0 0 0" xyz="0.05 0.0 0.0"/>
  </joint>
  <!-- <gazebo reference="${prefix}/tip_link">
      <xacro:gz_hand_link collide="${collision}"/>
    </gazebo> -->
  <link name="summit_xl_/wam/bhand/finger_2/tip_link">
    <inertial>
      <mass value="1E-6"/>
      <inertia ixx="1E-6" ixy="0" ixz="0" iyy="1E-6" iyz="0" izz="1E-6"/>
    </inertial>
  </link>
  <joint name="summit_xl_/wam/bhand/finger_3/med_joint" type="revolute">
    <parent link="summit_xl_/wam/bhand/bhand_palm_link"/>
    <child link="summit_xl_/wam/bhand/finger_3/med_link"/>
    <origin rpy="1.57079632679 0 1.57079632679" xyz="0 0.05 0.0754"/>
    <axis xyz="0 0 1"/>
    <limit effort="100" lower="0" upper="2.44346095279" velocity="5.00"/>
    <dynamics damping="0.11" friction="0"/>
  </joint>
  <gazebo reference="summit_xl_/wam/bhand/finger_3/med_joint">
    <provideFeedback>true</provideFeedback>
    <implicitSpringDamper>true</implicitSpringDamper>
    <!--<kp>0.0</kp>[> CFM <]-->
    <!--<kd>0.0</kd>[> ERP <]-->
    <!--<cfmDamping>true</cfmDamping>-->
    <!--<dynamics damping="5.5" friction="1"/>-->
  </gazebo>
  <gazebo reference="summit_xl_/wam/bhand/finger_3/med_link">
    <mu1>0.8</mu1>
    <mu2>0.8</mu2>
    <selfCollide>true</selfCollide>
  </gazebo>
  <link name="summit_xl_/wam/bhand/finger_3/med_link">
    <inertial>
      <origin xyz="0.023133 0.00078642 0.00052792"/>
      <mass value="0.062139"/>
      <inertia ixx="4.872e-006" ixy="1.7103e-006" ixz="3.4041e-008" iyy="7.6588e-005" iyz="2.3133e-008" izz="7.7733e-005"/>
    </inertial>
    <visual>
      <material name="WAMGrey">
        <color rgba="0.9 0.9 0.9 0.0"/>
      </material>
      <geometry>
        <mesh filename="package://summit_xl_description/urdf/models/sw_meshes/bhand/bhand_finger_med_link_fine.stl"/>
      </geometry>
    </visual>
    <collision>
      <geometry>
        <mesh filename="package://summit_xl_description/urdf/models/sw_meshes/bhand/bhand_finger_med_link_convex.dae"/>
      </geometry>
    </collision>
  </link>
  <joint name="summit_xl_/wam/bhand/finger_3/dist_joint" type="revolute">
    <parent link="summit_xl_/wam/bhand/finger_3/med_link"/>
    <child link="summit_xl_/wam/bhand/finger_3/dist_link"/>
    <origin rpy="0 0 0.785398163397" xyz="0.06994 0.003 0.0"/>
    <axis xyz="0 0 1"/>
    <limit effort="100" lower="0" upper="0.837758040957" velocity="5.00"/>
    <dynamics damping="0.11" friction="0"/>
  </joint>
  <gazebo reference="summit_xl_/wam/bhand/finger_3/dist_joint">
    <provideFeedback>true</provideFeedback>
    <implicitSpringDamper>true</implicitSpringDamper>
    <!--<kp>0.0</kp>[> CFM <]-->
    <!--<kd>0.0</kd>[> ERP <]-->
    <!--<cfmDamping>true</cfmDamping>-->
    <!--<dynamics damping="5.5" friction="1"/>-->
  </gazebo>
  <gazebo reference="summit_xl_/wam/bhand/finger_3/dist_link">
    <mu1>0.8</mu1>
    <mu2>0.8</mu2>
    <selfCollide>true</selfCollide>
  </gazebo>
  <link name="summit_xl_/wam/bhand/finger_3/dist_link">
    <inertial>
      <origin rpy="0 0 0" xyz="0.022825 0.0010491 0.0004203"/>
      <mass value="0.041377"/>
      <inertia ixx="3.1582e-006" ixy="1.4308e-006" ixz="1.0106e-007" iyy="3.8376e-005" iyz="0" izz="3.7275e-005"/>
    </inertial>
    <visual>
      <origin rpy="0 0 -0.785398163397"/>
      <material name="WAMGrey">
        <color rgba="0.9 0.9 0.9 0.0"/>
      </material>
      <geometry>
        <mesh filename="package://summit_xl_description/urdf/models/sw_meshes/bhand/bhand_finger_dist_link_fine.stl"/>
      </geometry>
    </visual>
    <collision>
      <origin rpy="0 0 -0.785398163397"/>
      <geometry>
        <mesh filename="package://summit_xl_description/urdf/models/sw_meshes/bhand/bhand_finger_dist_link_convex.dae"/>
      </geometry>
    </collision>
  </link>
  <joint name="summit_xl_/wam/bhand/finger_3/tip_joint" type="fixed">
    <parent link="summit_xl_/wam/bhand/finger_3/dist_link"/>
    <child link="summit_xl_/wam/bhand/finger_3/tip_link"/>
    <origin rpy="0 0 0" xyz="0.05 0.0 0.0"/>
  </joint>
  <!-- <gazebo reference="${prefix}/tip_link">
      <xacro:gz_hand_link collide="${collision}"/>
    </gazebo> -->
  <link name="summit_xl_/wam/bhand/finger_3/tip_link">
    <inertial>
      <mass value="1E-6"/>
      <inertia ixx="1E-6" ixy="0" ixz="0" iyy="1E-6" iyz="0" izz="1E-6"/>
    </inertial>
  </link>
  <!--Left Finger | Prox Joint transmission and motor -->
  <transmission name="summit_xl_/wam/bhand/finger_1/prox_joint_trans">
    <type>transmission_interface/SimpleTransmission</type>
    <joint name="summit_xl_/wam/bhand/finger_1/prox_joint">
      <hardwareInterface>hardware_interface/EffortJointInterface</hardwareInterface>
    </joint>
    <actuator name="summit_xl_/wam/bhand/finger_1/prox_joint_motor">
      <mechanicalReduction>1</mechanicalReduction>
      <hardwareInterface>hardware_interface/EffortJointInterface</hardwareInterface>
    </actuator>
  </transmission>
  <!--Left Finger | Mid Joint transmission and motor -->
  <transmission name="summit_xl_/wam/bhand/finger_1/med_joint_trans">
    <type>transmission_interface/SimpleTransmission</type>
    <joint name="summit_xl_/wam/bhand/finger_1/med_joint">
      <hardwareInterface>hardware_interface/EffortJointInterface</hardwareInterface>
    </joint>
    <actuator name="summit_xl_/wam/bhand/finger_1/med_joint_motor">
      <mechanicalReduction>1</mechanicalReduction>
      <hardwareInterface>hardware_interface/EffortJointInterface</hardwareInterface>
    </actuator>
  </transmission>
  <!--Left Finger | Dist Joint transmission and motor -->
  <transmission name="summit_xl_/wam/bhand/finger_1/dist_joint_trans">
    <type>transmission_interface/SimpleTransmission</type>
    <joint name="summit_xl_/wam/bhand/finger_1/dist_joint">
      <hardwareInterface>hardware_interface/EffortJointInterface</hardwareInterface>
    </joint>
    <actuator name="summit_xl_/wam/bhand/finger_1/dist_joint_motor">
      <mechanicalReduction>1</mechanicalReduction>
      <hardwareInterface>hardware_interface/EffortJointInterface</hardwareInterface>
    </actuator>
  </transmission>
  <!--Right Finger | Prox Joint transmission and motor -->
  <transmission name="summit_xl_/wam/bhand/finger_2/prox_joint_trans">
    <type>transmission_interface/SimpleTransmission</type>
    <joint name="summit_xl_/wam/bhand/finger_2/prox_joint">
      <hardwareInterface>hardware_interface/EffortJointInterface</hardwareInterface>
    </joint>
    <actuator name="summit_xl_/wam/bhand/finger_2/prox_joint_motor">
      <mechanicalReduction>1</mechanicalReduction>
      <hardwareInterface>hardware_interface/EffortJointInterface</hardwareInterface>
    </actuator>
  </transmission>
  <!--Right Finger | Mid Joint transmission and motor -->
  <transmission name="summit_xl_/wam/bhand/finger_2/med_joint_trans">
    <type>transmission_interface/SimpleTransmission</type>
    <joint name="summit_xl_/wam/bhand/finger_2/med_joint">
      <hardwareInterface>hardware_interface/EffortJointInterface</hardwareInterface>
    </joint>
    <actuator name="summit_xl_/wam/bhand/finger_2/med_joint_motor">
      <mechanicalReduction>1</mechanicalReduction>
      <hardwareInterface>hardware_interface/EffortJointInterface</hardwareInterface>
    </actuator>
  </transmission>
  <!--Right Finger | Dist Joint transmission and motor -->
  <transmission name="summit_xl_/wam/bhand/finger_2/dist_joint_trans">
    <type>transmission_interface/SimpleTransmission</type>
    <joint name="summit_xl_/wam/bhand/finger_2/dist_joint">
      <hardwareInterface>hardware_interface/EffortJointInterface</hardwareInterface>
    </joint>
    <actuator name="summit_xl_/wam/bhand/finger_2/dist_joint_motor">
      <mechanicalReduction>1</mechanicalReduction>
      <hardwareInterface>hardware_interface/EffortJointInterface</hardwareInterface>
    </actuator>
  </transmission>
  <!--Center Finger | Mid Joint transmission and motor -->
  <transmission name="summit_xl_/wam/bhand/finger_3/med_joint_trans">
    <type>transmission_interface/SimpleTransmission</type>
    <joint name="summit_xl_/wam/bhand/finger_3/med_joint">
      <hardwareInterface>hardware_interface/EffortJointInterface</hardwareInterface>
    </joint>
    <actuator name="summit_xl_/wam/bhand/finger_3/med_joint_motor">
      <mechanicalReduction>1</mechanicalReduction>
      <hardwareInterface>hardware_interface/EffortJointInterface</hardwareInterface>
    </actuator>
  </transmission>
  <!--Center Finger | Dist Joint transmission and motor -->
  <transmission name="summit_xl_/wam/bhand/finger_3/dist_joint_trans">
    <type>transmission_interface/SimpleTransmission</type>
    <joint name="summit_xl_/wam/bhand/finger_3/dist_joint">
      <hardwareInterface>hardware_interface/EffortJointInterface</hardwareInterface>
    </joint>
    <actuator name="summit_xl_/wam/bhand/finger_3/dist_joint_motor">
      <mechanicalReduction>1</mechanicalReduction>
      <hardwareInterface>hardware_interface/EffortJointInterface</hardwareInterface>
    </actuator>
  </transmission>
</robot>

